Workbook

Sheet Daily History Log
B1: VIX TERM STRUCTURE & MOVE INDEX — DAILY HISTORY LOG
B2: Matt Mattheisen-Shomer Analytics · Enter daily readings in blue cells · Regime flags update automatically
B3: VIX TERM STRUCTURE | T3: REGIME & SIGNAL | AA3: BREADTH
B4: Date | C4: Spot VIX | D4: VIX 1d Chg | E4: Apr /VXJ26 | F4: May /VXK26 | G4: Jun /VXM26 | H4: Jul /VXN26 | I4: Front Spread | J4: Second Spread | L4: MOVE Index | M4: MOVE 1d Chg | N4: MOVE 1d Chg % | P4: COR1M Index | Q4: COR1M 1d Chg | R4: COR1M 1d Chg % | S4: COR1M Regime | T4: VIX Regime | U4: MOVE Regime | V4: Combined Signal | W4: Signal | Y4: VIX Down Days (consec) | Z4: Reversion Watch Flag | AA4: $SPXA50R >50SMA % (enter 0-100) | AB4: McO (NYSE) + or -
B5: 03/09/2026 | C5: 27.95 | D5: - | E5: 24.55 | F5: 23.77 | G5: 23.1 | H5: - | I5: =IF(C5="","-",IF(E5<>"",C5-E5,IF(F5<>"",C5-F5,IF(G5<>"",C5-G5,IF(H5<>"",C5-H5,"-"))))) -> 3.4 | J5: =IF(C5="","-",IF(E5<>"",IF(F5<>"",C5-F5,IF(G5<>"",C5-G5,IF(H5<>"",C5-H5,"-"))),IF(F5<>"",IF(G5<>"",C5-G5,IF(H5<>"",C5-H5,"-")),IF(G5<>"",IF(H5<>"",C5-H5,"-"),"-")))) -> 4.18 | L5: 83.12 | M5: - | N5: - | P5: 27.83 | Q5: - | R5: - | S5: =IF(P5="","-",IF(P5<20,"CALM",IF(P5<40,"ELEVATED",IF(P5<60,"STRESSED","CRISIS")))) -> ELEVATED | T5: =IF(C5="","-",IF(C5<15,"EQUITY TREND",IF(C5<25,"NORMAL",IF(C5<35,"ELEVATED",IF(C5<45,"HIGH STRESS","CRISIS"))))) -> ELEVATED | U5: =IF(L5="","-",IF(L5<90,"NORMAL",IF(L5<120,"ELEVATED",IF(L5<160,"HIGH STRESS","CRISIS")))) -> NORMAL | V5: =IF(OR(C5="",L5=""),"-",IF(AND(C5<15,L5<90),"✦ FULL DEPLOYMENT",IF(AND(C5<25,L5<120),"STANDARD OPS",IF(AND(C5<35,L5<160),"REDUCE / BUILD LIST",IF(AND(C5<45,L5<160),"QUALITY ONLY","MAX CASH / WAIT"))))) -> REDUCE / BUILD LIST | W5: =IF(OR(C5="",L5=""),"-",IF(AND(C5<15,L5<90),"HOLD",IF(AND(C5<25,L5<120),"MONITOR",IF(AND(C5>=25,C5<35),"WAIT — DEFENSIVE",IF(C5>=35,"STRONG BUY","HOLD"))))) -> WAIT — DEFENSIVE | Y5: =IF(C5="","-",0) -> 0 | Z5: =IF(OR(C5="",L5="",P5=""),"-",IF(AND(C5<25,L5<95,P5<30,Y5>=3),"🟢 REVERSION WATCH",IF(AND(C5<27,L5<105,P5<35,Y5>=2),"🟡 APPROACHING","🔴 NOT YET"))) -> 🔴 NOT YET
B6: 03/10/2026 | C6: 25.06 | D6: =IF(OR(C6="",C5=""),"-",C6-C5) -> -2.89 | E6: 23.75 | F6: 22.12 | G6: 21.97 | H6: - | I6: =IF(C6="","-",IF(E6<>"",C6-E6,IF(F6<>"",C6-F6,IF(G6<>"",C6-G6,IF(H6<>"",C6-H6,"-"))))) -> 1.31 | J6: =IF(C6="","-",IF(E6<>"",IF(F6<>"",C6-F6,IF(G6<>"",C6-G6,IF(H6<>"",C6-H6,"-"))),IF(F6<>"",IF(G6<>"",C6-G6,IF(H6<>"",C6-H6,"-")),IF(G6<>"",IF(H6<>"",C6-H6,"-"),"-")))) -> 2.94 | L6: 80.45 | M6: =IF(OR(L6="",L5=""),"-",L6-L5) -> -2.67 | N6: =IF(OR(L6="",L5=""),"-",(L6-L5)/L5) -> -0.032122233 | P6: 28.97 | Q6: =IF(OR(P6="",P5=""),"-",P6-P5) -> 1.14 | R6: =IF(OR(P6="",P5=""),"-",(P6-P5)/P5) -> 0.04096299 | S6: =IF(P6="","-",IF(P6<20,"CALM",IF(P6<40,"ELEVATED",IF(P6<60,"STRESSED","CRISIS")))) -> ELEVATED | T6: =IF(C6="","-",IF(C6<15,"EQUITY TREND",IF(C6<25,"NORMAL",IF(C6<35,"ELEVATED",IF(C6<45,"HIGH STRESS","CRISIS"))))) -> ELEVATED | U6: =IF(L6="","-",IF(L6<90,"NORMAL",IF(L6<120,"ELEVATED",IF(L6<160,"HIGH STRESS","CRISIS")))) -> NORMAL | V6: =IF(OR(C6="",L6=""),"-",IF(AND(C6<15,L6<90),"✦ FULL DEPLOYMENT",IF(AND(C6<25,L6<120),"STANDARD OPS",IF(AND(C6<35,L6<160),"REDUCE / BUILD LIST",IF(AND(C6<45,L6<160),"QUALITY ONLY","MAX CASH / WAIT"))))) -> REDUCE / BUILD LIST | W6: =IF(OR(C6="",L6=""),"-",IF(AND(C6<15,L6<90),"HOLD",IF(AND(C6<25,L6<120),"MONITOR",IF(AND(C6>=25,C6<35),"WAIT — DEFENSIVE",IF(C6>=35,"STRONG BUY","HOLD"))))) -> WAIT — DEFENSIVE | Y6: =IF(C6="","-",IF(C6<C5,IF(Y5="-",1,Y5+1),0)) -> 1 | Z6: =IF(OR(C6="",L6="",P6=""),"-",IF(AND(C6<25,L6<95,P6<30,Y6>=3),"🟢 REVERSION WATCH",IF(AND(C6<27,L6<105,P6<35,Y6>=2),"🟡 APPROACHING","🔴 NOT YET"))) -> 🔴 NOT YET
B7: 03/11/2026 | C7: 24.23 | D7: =IF(OR(C7="",C6=""),"-",C7-C6) -> -0.83 | E7: 23.05 | F7: 22.95 | G7: 22.99 | H7: - | I7: =IF(C7="","-",IF(E7<>"",C7-E7,IF(F7<>"",C7-F7,IF(G7<>"",C7-G7,IF(H7<>"",C7-H7,"-"))))) -> 1.18 | J7: =IF(C7="","-",IF(E7<>"",IF(F7<>"",C7-F7,IF(G7<>"",C7-G7,IF(H7<>"",C7-H7,"-"))),IF(F7<>"",IF(G7<>"",C7-G7,IF(H7<>"",C7-H7,"-")),IF(G7<>"",IF(H7<>"",C7-H7,"-"),"-")))) -> 1.28 | L7: 78.59 | M7: =IF(OR(L7="",L6=""),"-",L7-L6) -> -1.86 | N7: =IF(OR(L7="",L6=""),"-",(L7-L6)/L6) -> -0.02311995 | P7: 29.18 | Q7: =IF(OR(P7="",P6=""),"-",P7-P6) -> 0.21 | R7: =IF(OR(P7="",P6=""),"-",(P7-P6)/P6) -> 0.0072488781 | S7: =IF(P7="","-",IF(P7<20,"CALM",IF(P7<40,"ELEVATED",IF(P7<60,"STRESSED","CRISIS")))) -> ELEVATED | T7: =IF(C7="","-",IF(C7<15,"EQUITY TREND",IF(C7<25,"NORMAL",IF(C7<35,"ELEVATED",IF(C7<45,"HIGH STRESS","CRISIS"))))) -> NORMAL | U7: =IF(L7="","-",IF(L7<90,"NORMAL",IF(L7<120,"ELEVATED",IF(L7<160,"HIGH STRESS","CRISIS")))) -> NORMAL | V7: =IF(OR(C7="",L7=""),"-",IF(AND(C7<15,L7<90),"✦ FULL DEPLOYMENT",IF(AND(C7<25,L7<120),"STANDARD OPS",IF(AND(C7<35,L7<160),"REDUCE / BUILD LIST",IF(AND(C7<45,L7<160),"QUALITY ONLY","MAX CASH / WAIT"))))) -> STANDARD OPS | W7: =IF(OR(C7="",L7=""),"-",IF(AND(C7<15,L7<90),"HOLD",IF(AND(C7<25,L7<120),"MONITOR",IF(AND(C7>=25,C7<35),"WAIT — DEFENSIVE",IF(C7>=35,"STRONG BUY","HOLD"))))) -> MONITOR | Y7: =IF(C7="","-",IF(C7<C6,IF(Y6="-",1,Y6+1),0)) -> 2 | Z7: =IF(OR(C7="",L7="",P7=""),"-",IF(AND(C7<25,L7<95,P7<30,Y7>=3),"🟢 REVERSION WATCH",IF(AND(C7<27,L7<105,P7<35,Y7>=2),"🟡 APPROACHING","🔴 NOT YET"))) -> 🟡 APPROACHING
B8: 03/12/2026 | C8: 25.89 | D8: =IF(OR(C8="",C7=""),"-",C8-C7) -> 1.66 | E8: 23.75 | F8: 23.53 | G8: 23.42 | H8: - | I8: =IF(C8="","-",IF(E8<>"",C8-E8,IF(F8<>"",C8-F8,IF(G8<>"",C8-G8,IF(H8<>"",C8-H8,"-"))))) -> 2.14 | J8: =IF(C8="","-",IF(E8<>"",IF(F8<>"",C8-F8,IF(G8<>"",C8-G8,IF(H8<>"",C8-H8,"-"))),IF(F8<>"",IF(G8<>"",C8-G8,IF(H8<>"",C8-H8,"-")),IF(G8<>"",IF(H8<>"",C8-H8,"-"),"-")))) -> 2.36 | L8: 95.3 | M8: =IF(OR(L8="",L7=""),"-",L8-L7) -> 16.71 | N8: =IF(OR(L8="",L7=""),"-",(L8-L7)/L7) -> 0.21262247 | P8: 35.52 | Q8: =IF(OR(P8="",P7=""),"-",P8-P7) -> 6.34 | R8: =IF(OR(P8="",P7=""),"-",(P8-P7)/P7) -> 0.2172721 | S8: =IF(P8="","-",IF(P8<20,"CALM",IF(P8<40,"ELEVATED",IF(P8<60,"STRESSED","CRISIS")))) -> ELEVATED | T8: =IF(C8="","-",IF(C8<15,"EQUITY TREND",IF(C8<25,"NORMAL",IF(C8<35,"ELEVATED",IF(C8<45,"HIGH STRESS","CRISIS"))))) -> ELEVATED | U8: =IF(L8="","-",IF(L8<90,"NORMAL",IF(L8<120,"ELEVATED",IF(L8<160,"HIGH STRESS","CRISIS")))) -> ELEVATED | V8: =IF(OR(C8="",L8=""),"-",IF(AND(C8<15,L8<90),"✦ FULL DEPLOYMENT",IF(AND(C8<25,L8<120),"STANDARD OPS",IF(AND(C8<35,L8<160),"REDUCE / BUILD LIST",IF(AND(C8<45,L8<160),"QUALITY ONLY","MAX CASH / WAIT"))))) -> REDUCE / BUILD LIST | W8: =IF(OR(C8="",L8=""),"-",IF(AND(C8<15,L8<90),"HOLD",IF(AND(C8<25,L8<120),"MONITOR",IF(AND(C8>=25,C8<35),"WAIT — DEFENSIVE",IF(C8>=35,"STRONG BUY","HOLD"))))) -> WAIT — DEFENSIVE | Y8: =IF(C8="","-",IF(C8<C7,IF(Y7="-",1,Y7+1),0)) -> 0 | Z8: =IF(OR(C8="",L8="",P8=""),"-",IF(AND(C8<25,L8<95,P8<30,Y8>=3),"🟢 REVERSION WATCH",IF(AND(C8<27,L8<105,P8<35,Y8>=2),"🟡 APPROACHING","🔴 NOT YET"))) -> 🔴 NOT YET
B9: 46094 | C9: 27.19 | D9: =IF(OR(C9="",C8=""),"-",C9-C8) -> 1.3 | E9: 24.92 | F9: 24.2 | G9: 21.55 | H9: - | I9: =IF(C9="","-",IF(E9<>"",C9-E9,IF(F9<>"",C9-F9,IF(G9<>"",C9-G9,IF(H9<>"",C9-H9,"-"))))) -> 2.27 | J9: =IF(C9="","-",IF(E9<>"",IF(F9<>"",C9-F9,IF(G9<>"",C9-G9,IF(H9<>"",C9-H9,"-"))),IF(F9<>"",IF(G9<>"",C9-G9,IF(H9<>"",C9-H9,"-")),IF(G9<>"",IF(H9<>"",C9-H9,"-"),"-")))) -> 2.99 | L9: 91.17 | M9: =IF(OR(L9="",L8=""),"-",L9-L8) -> -4.13 | N9: =IF(OR(L9="",L8=""),"-",(L9-L8)/L8) -> -0.043336831 | P9: 37.21 | Q9: =IF(OR(P9="",P8=""),"-",P9-P8) -> 1.69 | R9: =IF(OR(P9="",P8=""),"-",(P9-P8)/P8) -> 0.047578829 | S9: =IF(P9="","-",IF(P9<20,"CALM",IF(P9<40,"ELEVATED",IF(P9<60,"STRESSED","CRISIS")))) -> ELEVATED | T9: =IF(C9="","-",IF(C9<15,"EQUITY TREND",IF(C9<25,"NORMAL",IF(C9<35,"ELEVATED",IF(C9<45,"HIGH STRESS","CRISIS"))))) -> ELEVATED | U9: =IF(L9="","-",IF(L9<90,"NORMAL",IF(L9<120,"ELEVATED",IF(L9<160,"HIGH STRESS","CRISIS")))) -> ELEVATED | V9: =IF(OR(C9="",L9=""),"-",IF(AND(C9<15,L9<90),"✦ FULL DEPLOYMENT",IF(AND(C9<25,L9<120),"STANDARD OPS",IF(AND(C9<35,L9<160),"REDUCE / BUILD LIST",IF(AND(C9<45,L9<160),"QUALITY ONLY","MAX CASH / WAIT"))))) -> REDUCE / BUILD LIST | W9: =IF(OR(C9="",L9=""),"-",IF(AND(C9<15,L9<90),"HOLD",IF(AND(C9<25,L9<120),"MONITOR",IF(AND(C9>=25,C9<35),"WAIT — DEFENSIVE",IF(C9>=35,"STRONG BUY","HOLD"))))) -> WAIT — DEFENSIVE | Y9: =IF(C9="","-",IF(C9<C8,IF(Y8="-",1,Y8+1),0)) -> 0 | Z9: =IF(OR(C9="",L9="",P9=""),"-",IF(AND(C9<25,L9<95,P9<30,Y9>=3),"🟢 REVERSION WATCH",IF(AND(C9<27,L9<105,P9<35,Y9>=2),"🟡 APPROACHING","🔴 NOT YET"))) -> 🔴 NOT YET
B10: 46097 | C10: 23.55 | D10: =IF(OR(C10="",C9=""),"-",C10-C9) -> -3.64 | E10: 23 | F10: 22.86 | G10: 22.88 | H10: - | I10: =IF(C10="","-",IF(E10<>"",C10-E10,IF(F10<>"",C10-F10,IF(G10<>"",C10-G10,IF(H10<>"",C10-H10,"-"))))) -> 0.55 | J10: =IF(C10="","-",IF(E10<>"",IF(F10<>"",C10-F10,IF(G10<>"",C10-G10,IF(H10<>"",C10-H10,"-"))),IF(F10<>"",IF(G10<>"",C10-G10,IF(H10<>"",C10-H10,"-")),IF(G10<>"",IF(H10<>"",C10-H10,"-"),"-")))) -> 0.69 | L10: 85.25 | M10: =IF(OR(L10="",L9=""),"-",L10-L9) -> -5.92 | N10: =IF(OR(L10="",L9=""),"-",(L10-L9)/L9) -> -0.06493364 | P10: 29.56 | Q10: =IF(OR(P10="",P9=""),"-",P10-P9) -> -7.65 | R10: =IF(OR(P10="",P9=""),"-",(P10-P9)/P9) -> -0.2055899 | S10: =IF(P10="","-",IF(P10<20,"CALM",IF(P10<40,"ELEVATED",IF(P10<60,"STRESSED","CRISIS")))) -> ELEVATED | T10: =IF(C10="","-",IF(C10<15,"EQUITY TREND",IF(C10<25,"NORMAL",IF(C10<35,"ELEVATED",IF(C10<45,"HIGH STRESS","CRISIS"))))) -> NORMAL | U10: =IF(L10="","-",IF(L10<90,"NORMAL",IF(L10<120,"ELEVATED",IF(L10<160,"HIGH STRESS","CRISIS")))) -> NORMAL | V10: =IF(OR(C10="",L10=""),"-",IF(AND(C10<15,L10<90),"✦ FULL DEPLOYMENT",IF(AND(C10<25,L10<120),"STANDARD OPS",IF(AND(C10<35,L10<160),"REDUCE / BUILD LIST",IF(AND(C10<45,L10<160),"QUALITY ONLY","MAX CASH / WAIT"))))) -> STANDARD OPS | W10: =IF(OR(C10="",L10=""),"-",IF(AND(C10<15,L10<90),"HOLD",IF(AND(C10<25,L10<120),"MONITOR",IF(AND(C10>=25,C10<35),"WAIT — DEFENSIVE",IF(C10>=35,"STRONG BUY","HOLD"))))) -> MONITOR | Y10: =IF(C10="","-",IF(C10<C9,IF(Y9="-",1,Y9+1),0)) -> 1 | Z10: =IF(OR(C10="",L10="",P10=""),"-",IF(AND(C10<25,L10<95,P10<30,Y10>=3),"🟢 REVERSION WATCH",IF(AND(C10<27,L10<105,P10<35,Y10>=2),"🟡 APPROACHING","🔴 NOT YET"))) -> 🔴 NOT YET
B11: 46098 | C11: 22.37 | D11: =IF(OR(C11="",C10=""),"-",C11-C10) -> -1.18 | E11: 22.8 | F11: 22.7 | G11: 22.85 | H11: - | I11: =IF(C11="","-",IF(E11<>"",C11-E11,IF(F11<>"",C11-F11,IF(G11<>"",C11-G11,IF(H11<>"",C11-H11,"-"))))) -> -0.43 | J11: =IF(C11="","-",IF(E11<>"",IF(F11<>"",C11-F11,IF(G11<>"",C11-G11,IF(H11<>"",C11-H11,"-"))),IF(F11<>"",IF(G11<>"",C11-G11,IF(H11<>"",C11-H11,"-")),IF(G11<>"",IF(H11<>"",C11-H11,"-"),"-")))) -> -0.33 | L11: 79.23 | M11: =IF(OR(L11="",L10=""),"-",L11-L10) -> -6.02 | N11: =IF(OR(L11="",L10=""),"-",(L11-L10)/L10) -> -0.070615836 | P11: 29.5 | Q11: =IF(OR(P11="",P10=""),"-",P11-P10) -> -0.06 | R11: =IF(OR(P11="",P10=""),"-",(P11-P10)/P10) -> -0.00202977 | S11: =IF(P11="","-",IF(P11<20,"CALM",IF(P11<40,"ELEVATED",IF(P11<60,"STRESSED","CRISIS")))) -> ELEVATED | T11: =IF(C11="","-",IF(C11<15,"EQUITY TREND",IF(C11<25,"NORMAL",IF(C11<35,"ELEVATED",IF(C11<45,"HIGH STRESS","CRISIS"))))) -> NORMAL | U11: =IF(L11="","-",IF(L11<90,"NORMAL",IF(L11<120,"ELEVATED",IF(L11<160,"HIGH STRESS","CRISIS")))) -> NORMAL | V11: =IF(OR(C11="",L11=""),"-",IF(AND(C11<15,L11<90),"✦ FULL DEPLOYMENT",IF(AND(C11<25,L11<120),"STANDARD OPS",IF(AND(C11<35,L11<160),"REDUCE / BUILD LIST",IF(AND(C11<45,L11<160),"QUALITY ONLY","MAX CASH / WAIT"))))) -> STANDARD OPS | W11: =IF(OR(C11="",L11=""),"-",IF(AND(C11<15,L11<90),"HOLD",IF(AND(C11<25,L11<120),"MONITOR",IF(AND(C11>=25,C11<35),"WAIT — DEFENSIVE",IF(C11>=35,"STRONG BUY","HOLD"))))) -> MONITOR | Y11: =IF(C11="","-",IF(C11<C10,IF(Y10="-",1,Y10+1),0)) -> 2 | Z11: =IF(OR(C11="",L11="",P11=""),"-",IF(AND(C11<25,L11<95,P11<30,Y11>=3),"🟢 REVERSION WATCH",IF(AND(C11<27,L11<105,P11<35,Y11>=2),"🟡 APPROACHING","🔴 NOT YET"))) -> 🟡 APPROACHING
B12: 46099 | C12: 27.5 | D12: =IF(OR(C12="",C11=""),"-",C12-C11) -> 5.13 | E12: 21.5 | F12: 25.19 | G12: 24.66 | H12: - | I12: =IF(C12="","-",IF(E12<>"",C12-E12,IF(F12<>"",C12-F12,IF(G12<>"",C12-G12,IF(H12<>"",C12-H12,"-"))))) -> 6 | J12: =IF(C12="","-",IF(E12<>"",IF(F12<>"",C12-F12,IF(G12<>"",C12-G12,IF(H12<>"",C12-H12,"-"))),IF(F12<>"",IF(G12<>"",C12-G12,IF(H12<>"",C12-H12,"-")),IF(G12<>"",IF(H12<>"",C12-H12,"-"),"-")))) -> 2.31 | L12: 81.25 | M12: =IF(OR(L12="",L11=""),"-",L12-L11) -> 2.02 | N12: =IF(OR(L12="",L11=""),"-",(L12-L11)/L11) -> 0.025495393 | P12: 35.78 | Q12: =IF(OR(P12="",P11=""),"-",P12-P11) -> 6.28 | R12: =IF(OR(P12="",P11=""),"-",(P12-P11)/P11) -> 0.21288136 | S12: =IF(P12="","-",IF(P12<20,"CALM",IF(P12<40,"ELEVATED",IF(P12<60,"STRESSED","CRISIS")))) -> ELEVATED | T12: =IF(C12="","-",IF(C12<15,"EQUITY TREND",IF(C12<25,"NORMAL",IF(C12<35,"ELEVATED",IF(C12<45,"HIGH STRESS","CRISIS"))))) -> ELEVATED | U12: =IF(L12="","-",IF(L12<90,"NORMAL",IF(L12<120,"ELEVATED",IF(L12<160,"HIGH STRESS","CRISIS")))) -> NORMAL | V12: =IF(OR(C12="",L12=""),"-",IF(AND(C12<15,L12<90),"✦ FULL DEPLOYMENT",IF(AND(C12<25,L12<120),"STANDARD OPS",IF(AND(C12<35,L12<160),"REDUCE / BUILD LIST",IF(AND(C12<45,L12<160),"QUALITY ONLY","MAX CASH / WAIT"))))) -> REDUCE / BUILD LIST | W12: =IF(OR(C12="",L12=""),"-",IF(AND(C12<15,L12<90),"HOLD",IF(AND(C12<25,L12<120),"MONITOR",IF(AND(C12>=25,C12<35),"WAIT — DEFENSIVE",IF(C12>=35,"STRONG BUY","HOLD"))))) -> WAIT — DEFENSIVE | Y12: =IF(C12="","-",IF(C12<C11,IF(Y11="-",1,Y11+1),0)) -> 0 | Z12: =IF(OR(C12="",L12="",P12=""),"-",IF(AND(C12<25,L12<95,P12<30,Y12>=3),"🟢 REVERSION WATCH",IF(AND(C12<27,L12<105,P12<35,Y12>=2),"🟡 APPROACHING","🔴 NOT YET"))) -> 🔴 NOT YET
B13: 46100 | C13: 24.06 | D13: =IF(OR(C13="",C12=""),"-",C13-C12) -> -3.44 | E13: 23.85 | F13: 23.5 | G13: 21.55 | H13: - | I13: =IF(C13="","-",IF(E13<>"",C13-E13,IF(F13<>"",C13-F13,IF(G13<>"",C13-G13,IF(H13<>"",C13-H13,"-"))))) -> 0.21 | J13: =IF(C13="","-",IF(E13<>"",IF(F13<>"",C13-F13,IF(G13<>"",C13-G13,IF(H13<>"",C13-H13,"-"))),IF(F13<>"",IF(G13<>"",C13-G13,IF(H13<>"",C13-H13,"-")),IF(G13<>"",IF(H13<>"",C13-H13,"-"),"-")))) -> 0.56 | L13: 84.88 | M13: =IF(OR(L13="",L12=""),"-",L13-L12) -> 3.63 | N13: =IF(OR(L13="",L12=""),"-",(L13-L12)/L12) -> 0.044676923 | P13: 33.03 | Q13: =IF(OR(P13="",P12=""),"-",P13-P12) -> -2.75 | R13: =IF(OR(P13="",P12=""),"-",(P13-P12)/P12) -> -0.07685858 | S13: =IF(P13="","-",IF(P13<20,"CALM",IF(P13<40,"ELEVATED",IF(P13<60,"STRESSED","CRISIS")))) -> ELEVATED | T13: =IF(C13="","-",IF(C13<15,"EQUITY TREND",IF(C13<25,"NORMAL",IF(C13<35,"ELEVATED",IF(C13<45,"HIGH STRESS","CRISIS"))))) -> NORMAL | U13: =IF(L13="","-",IF(L13<90,"NORMAL",IF(L13<120,"ELEVATED",IF(L13<160,"HIGH STRESS","CRISIS")))) -> NORMAL | V13: =IF(OR(C13="",L13=""),"-",IF(AND(C13<15,L13<90),"✦ FULL DEPLOYMENT",IF(AND(C13<25,L13<120),"STANDARD OPS",IF(AND(C13<35,L13<160),"REDUCE / BUILD LIST",IF(AND(C13<45,L13<160),"QUALITY ONLY","MAX CASH / WAIT"))))) -> STANDARD OPS | W13: =IF(OR(C13="",L13=""),"-",IF(AND(C13<15,L13<90),"HOLD",IF(AND(C13<25,L13<120),"MONITOR",IF(AND(C13>=25,C13<35),"WAIT — DEFENSIVE",IF(C13>=35,"STRONG BUY","HOLD"))))) -> MONITOR | Y13: =IF(C13="","-",IF(C13<C12,IF(Y12="-",1,Y12+1),0)) -> 1 | Z13: =IF(OR(C13="",L13="",P13=""),"-",IF(AND(C13<25,L13<95,P13<30,Y13>=3),"🟢 REVERSION WATCH",IF(AND(C13<27,L13<105,P13<35,Y13>=2),"🟡 APPROACHING","🔴 NOT YET"))) -> 🔴 NOT YET
B14: 46101 | C14: 26.78 | D14: =IF(OR(C14="",C13=""),"-",C14-C13) -> 2.72 | E14: 25.2 | F14: 24.35 | G14: 24.08 | H14: - | I14: =IF(C14="","-",IF(E14<>"",C14-E14,IF(F14<>"",C14-F14,IF(G14<>"",C14-G14,IF(H14<>"",C14-H14,"-"))))) -> 1.58 | J14: =IF(C14="","-",IF(E14<>"",IF(F14<>"",C14-F14,IF(G14<>"",C14-G14,IF(H14<>"",C14-H14,"-"))),IF(F14<>"",IF(G14<>"",C14-G14,IF(H14<>"",C14-H14,"-")),IF(G14<>"",IF(H14<>"",C14-H14,"-"),"-")))) -> 2.43 | L14: 108.84 | M14: =IF(OR(L14="",L13=""),"-",L14-L13) -> 23.96 | N14: =IF(OR(L14="",L13=""),"-",(L14-L13)/L13) -> 0.28228087 | P14: 38.7 | Q14: =IF(OR(P14="",P13=""),"-",P14-P13) -> 5.67 | R14: =IF(OR(P14="",P13=""),"-",(P14-P13)/P13) -> 0.17166213 | S14: =IF(P14="","-",IF(P14<20,"CALM",IF(P14<40,"ELEVATED",IF(P14<60,"STRESSED","CRISIS")))) -> ELEVATED | T14: =IF(C14="","-",IF(C14<15,"EQUITY TREND",IF(C14<25,"NORMAL",IF(C14<35,"ELEVATED",IF(C14<45,"HIGH STRESS","CRISIS"))))) -> ELEVATED | U14: =IF(L14="","-",IF(L14<90,"NORMAL",IF(L14<120,"ELEVATED",IF(L14<160,"HIGH STRESS","CRISIS")))) -> ELEVATED | V14: =IF(OR(C14="",L14=""),"-",IF(AND(C14<15,L14<90),"✦ FULL DEPLOYMENT",IF(AND(C14<25,L14<120),"STANDARD OPS",IF(AND(C14<35,L14<160),"REDUCE / BUILD LIST",IF(AND(C14<45,L14<160),"QUALITY ONLY","MAX CASH / WAIT"))))) -> REDUCE / BUILD LIST | W14: =IF(OR(C14="",L14=""),"-",IF(AND(C14<15,L14<90),"HOLD",IF(AND(C14<25,L14<120),"MONITOR",IF(AND(C14>=25,C14<35),"WAIT — DEFENSIVE",IF(C14>=35,"STRONG BUY","HOLD"))))) -> WAIT — DEFENSIVE | Y14: =IF(C14="","-",IF(C14<C13,IF(Y13="-",1,Y13+1),0)) -> 0 | Z14: =IF(OR(C14="",L14="",P14=""),"-",IF(AND(C14<25,L14<95,P14<30,Y14>=3),"🟢 REVERSION WATCH",IF(AND(C14<27,L14<105,P14<35,Y14>=2),"🟡 APPROACHING","🔴 NOT YET"))) -> 🔴 NOT YET
B15: 46104 | C15: 26.15 | D15: =IF(OR(C15="",C14=""),"-",C15-C14) -> -0.63 | E15: 24.25 | F15: 23.55 | G15: 23.4 | H15: - | I15: =IF(C15="","-",IF(E15<>"",C15-E15,IF(F15<>"",C15-F15,IF(G15<>"",C15-G15,IF(H15<>"",C15-H15,"-"))))) -> 1.9 | J15: =IF(C15="","-",IF(E15<>"",IF(F15<>"",C15-F15,IF(G15<>"",C15-G15,IF(H15<>"",C15-H15,"-"))),IF(F15<>"",IF(G15<>"",C15-G15,IF(H15<>"",C15-H15,"-")),IF(G15<>"",IF(H15<>"",C15-H15,"-"),"-")))) -> 2.6 | L15: 98.15 | M15: =IF(OR(L15="",L14=""),"-",L15-L14) -> -10.69 | N15: =IF(OR(L15="",L14=""),"-",(L15-L14)/L14) -> -0.098217567 | P15: 37.61 | Q15: =IF(OR(P15="",P14=""),"-",P15-P14) -> -1.09 | R15: =IF(OR(P15="",P14=""),"-",(P15-P14)/P14) -> -0.028165375 | S15: =IF(P15="","-",IF(P15<20,"CALM",IF(P15<40,"ELEVATED",IF(P15<60,"STRESSED","CRISIS")))) -> ELEVATED | T15: =IF(C15="","-",IF(C15<15,"EQUITY TREND",IF(C15<25,"NORMAL",IF(C15<35,"ELEVATED",IF(C15<45,"HIGH STRESS","CRISIS"))))) -> ELEVATED | U15: =IF(L15="","-",IF(L15<90,"NORMAL",IF(L15<120,"ELEVATED",IF(L15<160,"HIGH STRESS","CRISIS")))) -> ELEVATED | V15: =IF(OR(C15="",L15=""),"-",IF(AND(C15<15,L15<90),"✦ FULL DEPLOYMENT",IF(AND(C15<25,L15<120),"STANDARD OPS",IF(AND(C15<35,L15<160),"REDUCE / BUILD LIST",IF(AND(C15<45,L15<160),"QUALITY ONLY","MAX CASH / WAIT"))))) -> REDUCE / BUILD LIST | W15: =IF(OR(C15="",L15=""),"-",IF(AND(C15<15,L15<90),"HOLD",IF(AND(C15<25,L15<120),"MONITOR",IF(AND(C15>=25,C15<35),"WAIT — DEFENSIVE",IF(C15>=35,"STRONG BUY","HOLD"))))) -> WAIT — DEFENSIVE | Y15: =IF(C15="","-",IF(C15<C14,IF(Y14="-",1,Y14+1),0)) -> 1 | Z15: =IF(OR(C15="",L15="",P15=""),"-",IF(AND(C15<25,L15<95,P15<30,Y15>=3),"🟢 REVERSION WATCH",IF(AND(C15<27,L15<105,P15<35,Y15>=2),"🟡 APPROACHING","🔴 NOT YET"))) -> 🔴 NOT YET
B16: 46105 | C16: 26.86 | D16: =IF(OR(C16="",C15=""),"-",C16-C15) -> 0.71 | E16: 24.95 | F16: 24.15 | G16: 23.82 | H16: - | I16: =IF(C16="","-",IF(E16<>"",C16-E16,IF(F16<>"",C16-F16,IF(G16<>"",C16-G16,IF(H16<>"",C16-H16,"-"))))) -> 1.91 | J16: =IF(C16="","-",IF(E16<>"",IF(F16<>"",C16-F16,IF(G16<>"",C16-G16,IF(H16<>"",C16-H16,"-"))),IF(F16<>"",IF(G16<>"",C16-G16,IF(H16<>"",C16-H16,"-")),IF(G16<>"",IF(H16<>"",C16-H16,"-"),"-")))) -> 2.71 | L16: 103.01 | M16: =IF(OR(L16="",L15=""),"-",L16-L15) -> 4.86 | N16: =IF(OR(L16="",L15=""),"-",(L16-L15)/L15) -> 0.049516047 | P16: 37.49 | Q16: =IF(OR(P16="",P15=""),"-",P16-P15) -> -0.12 | R16: =IF(OR(P16="",P15=""),"-",(P16-P15)/P15) -> -0.0031906408 | S16: =IF(P16="","-",IF(P16<20,"CALM",IF(P16<40,"ELEVATED",IF(P16<60,"STRESSED","CRISIS")))) -> ELEVATED | T16: =IF(C16="","-",IF(C16<15,"EQUITY TREND",IF(C16<25,"NORMAL",IF(C16<35,"ELEVATED",IF(C16<45,"HIGH STRESS","CRISIS"))))) -> ELEVATED | U16: =IF(L16="","-",IF(L16<90,"NORMAL",IF(L16<120,"ELEVATED",IF(L16<160,"HIGH STRESS","CRISIS")))) -> ELEVATED | V16: =IF(OR(C16="",L16=""),"-",IF(AND(C16<15,L16<90),"✦ FULL DEPLOYMENT",IF(AND(C16<25,L16<120),"STANDARD OPS",IF(AND(C16<35,L16<160),"REDUCE / BUILD LIST",IF(AND(C16<45,L16<160),"QUALITY ONLY","MAX CASH / WAIT"))))) -> REDUCE / BUILD LIST | W16: =IF(OR(C16="",L16=""),"-",IF(AND(C16<15,L16<90),"HOLD",IF(AND(C16<25,L16<120),"MONITOR",IF(AND(C16>=25,C16<35),"WAIT — DEFENSIVE",IF(C16>=35,"STRONG BUY","HOLD"))))) -> WAIT — DEFENSIVE | Y16: =IF(C16="","-",IF(C16<C15,IF(Y15="-",1,Y15+1),0)) -> 0 | Z16: =IF(OR(C16="",L16="",P16=""),"-",IF(AND(C16<25,L16<95,P16<30,Y16>=3),"🟢 REVERSION WATCH",IF(AND(C16<27,L16<105,P16<35,Y16>=2),"🟡 APPROACHING","🔴 NOT YET"))) -> 🔴 NOT YET
B17: 46106 | C17: 25.33 | D17: =IF(OR(C17="",C16=""),"-",C17-C16) -> -1.53 | E17: 24.3 | F17: 23.75 | G17: 23.54 | H17: - | I17: =IF(C17="","-",IF(E17<>"",C17-E17,IF(F17<>"",C17-F17,IF(G17<>"",C17-G17,IF(H17<>"",C17-H17,"-"))))) -> 1.03 | J17: =IF(C17="","-",IF(E17<>"",IF(F17<>"",C17-F17,IF(G17<>"",C17-G17,IF(H17<>"",C17-H17,"-"))),IF(F17<>"",IF(G17<>"",C17-G17,IF(H17<>"",C17-H17,"-")),IF(G17<>"",IF(H17<>"",C17-H17,"-"),"-")))) -> 1.58 | L17: 97.59 | M17: =IF(OR(L17="",L16=""),"-",L17-L16) -> -5.42 | N17: =IF(OR(L17="",L16=""),"-",(L17-L16)/L16) -> -0.052616251 | P17: 34.76 | Q17: =IF(OR(P17="",P16=""),"-",P17-P16) -> -2.73 | R17: =IF(OR(P17="",P16=""),"-",(P17-P16)/P16) -> -0.072819419 | S17: =IF(P17="","-",IF(P17<20,"CALM",IF(P17<40,"ELEVATED",IF(P17<60,"STRESSED","CRISIS")))) -> ELEVATED | T17: =IF(C17="","-",IF(C17<15,"EQUITY TREND",IF(C17<25,"NORMAL",IF(C17<35,"ELEVATED",IF(C17<45,"HIGH STRESS","CRISIS"))))) -> ELEVATED | U17: =IF(L17="","-",IF(L17<90,"NORMAL",IF(L17<120,"ELEVATED",IF(L17<160,"HIGH STRESS","CRISIS")))) -> ELEVATED | V17: =IF(OR(C17="",L17=""),"-",IF(AND(C17<15,L17<90),"✦ FULL DEPLOYMENT",IF(AND(C17<25,L17<120),"STANDARD OPS",IF(AND(C17<35,L17<160),"REDUCE / BUILD LIST",IF(AND(C17<45,L17<160),"QUALITY ONLY","MAX CASH / WAIT"))))) -> REDUCE / BUILD LIST | W17: =IF(OR(C17="",L17=""),"-",IF(AND(C17<15,L17<90),"HOLD",IF(AND(C17<25,L17<120),"MONITOR",IF(AND(C17>=25,C17<35),"WAIT — DEFENSIVE",IF(C17>=35,"STRONG BUY","HOLD"))))) -> WAIT — DEFENSIVE | Y17: =IF(C17="","-",IF(C17<C16,IF(Y16="-",1,Y16+1),0)) -> 1 | Z17: =IF(OR(C17="",L17="",P17=""),"-",IF(AND(C17<25,L17<95,P17<30,Y17>=3),"🟢 REVERSION WATCH",IF(AND(C17<27,L17<105,P17<35,Y17>=2),"🟡 APPROACHING","🔴 NOT YET"))) -> 🔴 NOT YET
B18: 46107 | C18: 27.44 | D18: =IF(OR(C18="",C17=""),"-",C18-C17) -> 2.11 | E18: 25.83 | F18: 24.75 | G18: 24.29 | H18: - | I18: =IF(C18="","-",IF(E18<>"",C18-E18,IF(F18<>"",C18-F18,IF(G18<>"",C18-G18,IF(H18<>"",C18-H18,"-"))))) -> 1.61 | J18: =IF(C18="","-",IF(E18<>"",IF(F18<>"",C18-F18,IF(G18<>"",C18-G18,IF(H18<>"",C18-H18,"-"))),IF(F18<>"",IF(G18<>"",C18-G18,IF(H18<>"",C18-H18,"-")),IF(G18<>"",IF(H18<>"",C18-H18,"-"),"-")))) -> 2.69 | L18: 115.02 | M18: =IF(OR(L18="",L17=""),"-",L18-L17) -> 17.43 | N18: =IF(OR(L18="",L17=""),"-",(L18-L17)/L17) -> 0.17860437 | P18: 36.19 | Q18: =IF(OR(P18="",P17=""),"-",P18-P17) -> 1.43 | R18: =IF(OR(P18="",P17=""),"-",(P18-P17)/P17) -> 0.041139241 | S18: =IF(P18="","-",IF(P18<20,"CALM",IF(P18<40,"ELEVATED",IF(P18<60,"STRESSED","CRISIS")))) -> ELEVATED | T18: =IF(C18="","-",IF(C18<15,"EQUITY TREND",IF(C18<25,"NORMAL",IF(C18<35,"ELEVATED",IF(C18<45,"HIGH STRESS","CRISIS"))))) -> ELEVATED | U18: =IF(L18="","-",IF(L18<90,"NORMAL",IF(L18<120,"ELEVATED",IF(L18<160,"HIGH STRESS","CRISIS")))) -> ELEVATED | V18: =IF(OR(C18="",L18=""),"-",IF(AND(C18<15,L18<90),"✦ FULL DEPLOYMENT",IF(AND(C18<25,L18<120),"STANDARD OPS",IF(AND(C18<35,L18<160),"REDUCE / BUILD LIST",IF(AND(C18<45,L18<160),"QUALITY ONLY","MAX CASH / WAIT"))))) -> REDUCE / BUILD LIST | W18: =IF(OR(C18="",L18=""),"-",IF(AND(C18<15,L18<90),"HOLD",IF(AND(C18<25,L18<120),"MONITOR",IF(AND(C18>=25,C18<35),"WAIT — DEFENSIVE",IF(C18>=35,"STRONG BUY","HOLD"))))) -> WAIT — DEFENSIVE | Y18: =IF(C18="","-",IF(C18<C17,IF(Y17="-",1,Y17+1),0)) -> 0 | Z18: =IF(OR(C18="",L18="",P18=""),"-",IF(AND(C18<25,L18<95,P18<30,Y18>=3),"🟢 REVERSION WATCH",IF(AND(C18<27,L18<105,P18<35,Y18>=2),"🟡 APPROACHING","🔴 NOT YET"))) -> 🔴 NOT YET
B19: 46108 | C19: 31.05 | D19: =IF(OR(C19="",C18=""),"-",C19-C18) -> 3.61 | E19: 28.53 | F19: 26.52 | G19: 25.65 | H19: - | I19: =IF(C19="","-",IF(E19<>"",C19-E19,IF(F19<>"",C19-F19,IF(G19<>"",C19-G19,IF(H19<>"",C19-H19,"-"))))) -> 2.52 | J19: =IF(C19="","-",IF(E19<>"",IF(F19<>"",C19-F19,IF(G19<>"",C19-G19,IF(H19<>"",C19-H19,"-"))),IF(F19<>"",IF(G19<>"",C19-G19,IF(H19<>"",C19-H19,"-")),IF(G19<>"",IF(H19<>"",C19-H19,"-"),"-")))) -> 4.53 | L19: 111.95 | M19: =IF(OR(L19="",L18=""),"-",L19-L18) -> -3.07 | N19: =IF(OR(L19="",L18=""),"-",(L19-L18)/L18) -> -0.02669101 | P19: 41.87 | Q19: =IF(OR(P19="",P18=""),"-",P19-P18) -> 5.68 | R19: =IF(OR(P19="",P18=""),"-",(P19-P18)/P18) -> 0.15694943 | S19: =IF(P19="","-",IF(P19<20,"CALM",IF(P19<40,"ELEVATED",IF(P19<60,"STRESSED","CRISIS")))) -> STRESSED | T19: =IF(C19="","-",IF(C19<15,"EQUITY TREND",IF(C19<25,"NORMAL",IF(C19<35,"ELEVATED",IF(C19<45,"HIGH STRESS","CRISIS"))))) -> ELEVATED | U19: =IF(L19="","-",IF(L19<90,"NORMAL",IF(L19<120,"ELEVATED",IF(L19<160,"HIGH STRESS","CRISIS")))) -> ELEVATED | V19: =IF(OR(C19="",L19=""),"-",IF(AND(C19<15,L19<90),"✦ FULL DEPLOYMENT",IF(AND(C19<25,L19<120),"STANDARD OPS",IF(AND(C19<35,L19<160),"REDUCE / BUILD LIST",IF(AND(C19<45,L19<160),"QUALITY ONLY","MAX CASH / WAIT"))))) -> REDUCE / BUILD LIST | W19: =IF(OR(C19="",L19=""),"-",IF(AND(C19<15,L19<90),"HOLD",IF(AND(C19<25,L19<120),"MONITOR",IF(AND(C19>=25,C19<35),"WAIT — DEFENSIVE",IF(C19>=35,"STRONG BUY","HOLD"))))) -> WAIT — DEFENSIVE | Y19: =IF(C19="","-",IF(C19<C18,IF(Y18="-",1,Y18+1),0)) -> 0 | Z19: =IF(OR(C19="",L19="",P19=""),"-",IF(AND(C19<25,L19<95,P19<30,Y19>=3),"🟢 REVERSION WATCH",IF(AND(C19<27,L19<105,P19<35,Y19>=2),"🟡 APPROACHING","🔴 NOT YET"))) -> 🔴 NOT YET
B20: 46111 | C20: 30.62 | D20: =IF(OR(C20="",C19=""),"-",C20-C19) -> -0.43 | E20: 28.45 | F20: 26.55 | G20: 25.75 | H20: - | I20: =IF(C20="","-",IF(E20<>"",C20-E20,IF(F20<>"",C20-F20,IF(G20<>"",C20-G20,IF(H20<>"",C20-H20,"-"))))) -> 2.17 | J20: =IF(C20="","-",IF(E20<>"",IF(F20<>"",C20-F20,IF(G20<>"",C20-G20,IF(H20<>"",C20-H20,"-"))),IF(F20<>"",IF(G20<>"",C20-G20,IF(H20<>"",C20-H20,"-")),IF(G20<>"",IF(H20<>"",C20-H20,"-"),"-")))) -> 4.07 | L20: 108.33 | M20: =IF(OR(L20="",L19=""),"-",L20-L19) -> -3.62 | N20: =IF(OR(L20="",L19=""),"-",(L20-L19)/L19) -> -0.032335864 | P20: 37.61 | Q20: =IF(OR(P20="",P19=""),"-",P20-P19) -> -4.26 | R20: =IF(OR(P20="",P19=""),"-",(P20-P19)/P19) -> -0.10174349 | S20: =IF(P20="","-",IF(P20<20,"CALM",IF(P20<40,"ELEVATED",IF(P20<60,"STRESSED","CRISIS")))) -> ELEVATED | T20: =IF(C20="","-",IF(C20<15,"EQUITY TREND",IF(C20<25,"NORMAL",IF(C20<35,"ELEVATED",IF(C20<45,"HIGH STRESS","CRISIS"))))) -> ELEVATED | U20: =IF(L20="","-",IF(L20<90,"NORMAL",IF(L20<120,"ELEVATED",IF(L20<160,"HIGH STRESS","CRISIS")))) -> ELEVATED | V20: =IF(OR(C20="",L20=""),"-",IF(AND(C20<15,L20<90),"✦ FULL DEPLOYMENT",IF(AND(C20<25,L20<120),"STANDARD OPS",IF(AND(C20<35,L20<160),"REDUCE / BUILD LIST",IF(AND(C20<45,L20<160),"QUALITY ONLY","MAX CASH / WAIT"))))) -> REDUCE / BUILD LIST | W20: =IF(OR(C20="",L20=""),"-",IF(AND(C20<15,L20<90),"HOLD",IF(AND(C20<25,L20<120),"MONITOR",IF(AND(C20>=25,C20<35),"WAIT — DEFENSIVE",IF(C20>=35,"STRONG BUY","HOLD"))))) -> WAIT — DEFENSIVE | Y20: =IF(C20="","-",IF(C20<C19,IF(Y19="-",1,Y19+1),0)) -> 1 | Z20: =IF(OR(C20="",L20="",P20=""),"-",IF(AND(C20<25,L20<95,P20<30,Y20>=3),"🟢 REVERSION WATCH",IF(AND(C20<27,L20<105,P20<35,Y20>=2),"🟡 APPROACHING","🔴 NOT YET"))) -> 🔴 NOT YET | AA20: 19 | AB20: -112
B21: 46112 | C21: 25.35 | D21: =IF(OR(C21="",C20=""),"-",C21-C20) -> -5.27 | E21: 25 | F21: 24.42 | G21: 24.25 | H21: - | I21: =IF(C21="","-",IF(E21<>"",C21-E21,IF(F21<>"",C21-F21,IF(G21<>"",C21-G21,IF(H21<>"",C21-H21,"-"))))) -> 0.35 | J21: =IF(C21="","-",IF(E21<>"",IF(F21<>"",C21-F21,IF(G21<>"",C21-G21,IF(H21<>"",C21-H21,"-"))),IF(F21<>"",IF(G21<>"",C21-G21,IF(H21<>"",C21-H21,"-")),IF(G21<>"",IF(H21<>"",C21-H21,"-"),"-")))) -> 0.93 | L21: 96.05 | M21: =IF(OR(L21="",L20=""),"-",L21-L20) -> -12.28 | N21: =IF(OR(L21="",L20=""),"-",(L21-L20)/L20) -> -0.11335733 | P21: 28.52 | Q21: =IF(OR(P21="",P20=""),"-",P21-P20) -> -9.09 | R21: =IF(OR(P21="",P20=""),"-",(P21-P20)/P20) -> -0.24169104 | S21: =IF(P21="","-",IF(P21<20,"CALM",IF(P21<40,"ELEVATED",IF(P21<60,"STRESSED","CRISIS")))) -> ELEVATED | T21: =IF(C21="","-",IF(C21<15,"EQUITY TREND",IF(C21<25,"NORMAL",IF(C21<35,"ELEVATED",IF(C21<45,"HIGH STRESS","CRISIS"))))) -> ELEVATED | U21: =IF(L21="","-",IF(L21<90,"NORMAL",IF(L21<120,"ELEVATED",IF(L21<160,"HIGH STRESS","CRISIS")))) -> ELEVATED | V21: =IF(OR(C21="",L21=""),"-",IF(AND(C21<15,L21<90),"✦ FULL DEPLOYMENT",IF(AND(C21<25,L21<120),"STANDARD OPS",IF(AND(C21<35,L21<160),"REDUCE / BUILD LIST",IF(AND(C21<45,L21<160),"QUALITY ONLY","MAX CASH / WAIT"))))) -> REDUCE / BUILD LIST | W21: =IF(OR(C21="",L21=""),"-",IF(AND(C21<15,L21<90),"HOLD",IF(AND(C21<25,L21<120),"MONITOR",IF(AND(C21>=25,C21<35),"WAIT — DEFENSIVE",IF(C21>=35,"STRONG BUY","HOLD"))))) -> WAIT — DEFENSIVE | Y21: =IF(C21="","-",IF(C21<C20,IF(Y20="-",1,Y20+1),0)) -> 2 | Z21: =IF(OR(C21="",L21="",P21=""),"-",IF(AND(C21<25,L21<95,P21<30,Y21>=3),"🟢 REVERSION WATCH",IF(AND(C21<27,L21<105,P21<35,Y21>=2),"🟡 APPROACHING","🔴 NOT YET"))) -> 🟡 APPROACHING | AA21: 24 | AB21: -17
B22: 46113 | C22: 24.54 | D22: =IF(OR(C22="",C21=""),"-",C22-C21) -> -0.81 | E22: 24.35 | F22: 23.87 | G22: 23.75 | H22: - | I22: =IF(C22="","-",IF(E22<>"",C22-E22,IF(F22<>"",C22-F22,IF(G22<>"",C22-G22,IF(H22<>"",C22-H22,"-"))))) -> 0.19 | J22: =IF(C22="","-",IF(E22<>"",IF(F22<>"",C22-F22,IF(G22<>"",C22-G22,IF(H22<>"",C22-H22,"-"))),IF(F22<>"",IF(G22<>"",C22-G22,IF(H22<>"",C22-H22,"-")),IF(G22<>"",IF(H22<>"",C22-H22,"-"),"-")))) -> 0.67 | L22: 90.19 | M22: =IF(OR(L22="",L21=""),"-",L22-L21) -> -5.86 | N22: =IF(OR(L22="",L21=""),"-",(L22-L21)/L21) -> -0.061009891 | P22: 26.08 | Q22: =IF(OR(P22="",P21=""),"-",P22-P21) -> -2.44 | R22: =IF(OR(P22="",P21=""),"-",(P22-P21)/P21) -> -0.085553997 | S22: =IF(P22="","-",IF(P22<20,"CALM",IF(P22<40,"ELEVATED",IF(P22<60,"STRESSED","CRISIS")))) -> ELEVATED | T22: =IF(C22="","-",IF(C22<15,"EQUITY TREND",IF(C22<25,"NORMAL",IF(C22<35,"ELEVATED",IF(C22<45,"HIGH STRESS","CRISIS"))))) -> NORMAL | U22: =IF(L22="","-",IF(L22<90,"NORMAL",IF(L22<120,"ELEVATED",IF(L22<160,"HIGH STRESS","CRISIS")))) -> ELEVATED | V22: =IF(OR(C22="",L22=""),"-",IF(AND(C22<15,L22<90),"✦ FULL DEPLOYMENT",IF(AND(C22<25,L22<120),"STANDARD OPS",IF(AND(C22<35,L22<160),"REDUCE / BUILD LIST",IF(AND(C22<45,L22<160),"QUALITY ONLY","MAX CASH / WAIT"))))) -> STANDARD OPS | W22: =IF(OR(C22="",L22=""),"-",IF(AND(C22<15,L22<90),"HOLD",IF(AND(C22<25,L22<120),"MONITOR",IF(AND(C22>=25,C22<35),"WAIT — DEFENSIVE",IF(C22>=35,"STRONG BUY","HOLD"))))) -> MONITOR | Y22: =IF(C22="","-",IF(C22<C21,IF(Y21="-",1,Y21+1),0)) -> 3 | Z22: =IF(OR(C22="",L22="",P22=""),"-",IF(AND(C22<25,L22<95,P22<30,Y22>=3),"🟢 REVERSION WATCH",IF(AND(C22<27,L22<105,P22<35,Y22>=2),"🟡 APPROACHING","🔴 NOT YET"))) -> 🟢 REVERSION WATCH | AA22: 26 | AB22: 29
B23: 46114 | C23: 23.87 | D23: =IF(OR(C23="",C22=""),"-",C23-C22) -> -0.67 | E23: 24.66 | F23: 24.1 | G23: 23.85 | H23: - | I23: =IF(C23="","-",IF(E23<>"",C23-E23,IF(F23<>"",C23-F23,IF(G23<>"",C23-G23,IF(H23<>"",C23-H23,"-"))))) -> -0.79 | J23: =IF(C23="","-",IF(E23<>"",IF(F23<>"",C23-F23,IF(G23<>"",C23-G23,IF(H23<>"",C23-H23,"-"))),IF(F23<>"",IF(G23<>"",C23-G23,IF(H23<>"",C23-H23,"-")),IF(G23<>"",IF(H23<>"",C23-H23,"-"),"-")))) -> -0.23 | L23: 84.41 | M23: =IF(OR(L23="",L22=""),"-",L23-L22) -> -5.78 | N23: =IF(OR(L23="",L22=""),"-",(L23-L22)/L22) -> -0.064086928 | P23: 25 | Q23: =IF(OR(P23="",P22=""),"-",P23-P22) -> -1.08 | R23: =IF(OR(P23="",P22=""),"-",(P23-P22)/P22) -> -0.041411043 | S23: =IF(P23="","-",IF(P23<20,"CALM",IF(P23<40,"ELEVATED",IF(P23<60,"STRESSED","CRISIS")))) -> ELEVATED | T23: =IF(C23="","-",IF(C23<15,"EQUITY TREND",IF(C23<25,"NORMAL",IF(C23<35,"ELEVATED",IF(C23<45,"HIGH STRESS","CRISIS"))))) -> NORMAL | U23: =IF(L23="","-",IF(L23<90,"NORMAL",IF(L23<120,"ELEVATED",IF(L23<160,"HIGH STRESS","CRISIS")))) -> NORMAL | V23: =IF(OR(C23="",L23=""),"-",IF(AND(C23<15,L23<90),"✦ FULL DEPLOYMENT",IF(AND(C23<25,L23<120),"STANDARD OPS",IF(AND(C23<35,L23<160),"REDUCE / BUILD LIST",IF(AND(C23<45,L23<160),"QUALITY ONLY","MAX CASH / WAIT"))))) -> STANDARD OPS | W23: =IF(OR(C23="",L23=""),"-",IF(AND(C23<15,L23<90),"HOLD",IF(AND(C23<25,L23<120),"MONITOR",IF(AND(C23>=25,C23<35),"WAIT — DEFENSIVE",IF(C23>=35,"STRONG BUY","HOLD"))))) -> MONITOR | Y23: =IF(C23="","-",IF(C23<C22,IF(Y22="-",1,Y22+1),0)) -> 4 | Z23: =IF(OR(C23="",L23="",P23=""),"-",IF(AND(C23<25,L23<95,P23<30,Y23>=3),"🟢 REVERSION WATCH",IF(AND(C23<27,L23<105,P23<35,Y23>=2),"🟡 APPROACHING","🔴 NOT YET"))) -> 🟢 REVERSION WATCH | AA23: 28 | AB23: 51
B24: 46118 | C24: 24.17 | D24: =IF(OR(C24="",C23=""),"-",C24-C23) -> 0.3 | E24: 23.76 | F24: 23.28 | G24: 23.22 | H24: - | I24: =IF(C24="","-",IF(E24<>"",C24-E24,IF(F24<>"",C24-F24,IF(G24<>"",C24-G24,IF(H24<>"",C24-H24,"-"))))) -> 0.41 | J24: =IF(C24="","-",IF(E24<>"",IF(F24<>"",C24-F24,IF(G24<>"",C24-G24,IF(H24<>"",C24-H24,"-"))),IF(F24<>"",IF(G24<>"",C24-G24,IF(H24<>"",C24-H24,"-")),IF(G24<>"",IF(H24<>"",C24-H24,"-"),"-")))) -> 0.89 | L24: 81.68 | M24: =IF(OR(L24="",L23=""),"-",L24-L23) -> -2.73 | N24: =IF(OR(L24="",L23=""),"-",(L24-L23)/L23) -> -0.03234214 | P24: 24.08 | Q24: =IF(OR(P24="",P23=""),"-",P24-P23) -> -0.92 | R24: =IF(OR(P24="",P23=""),"-",(P24-P23)/P23) -> -0.0368 | S24: =IF(P24="","-",IF(P24<20,"CALM",IF(P24<40,"ELEVATED",IF(P24<60,"STRESSED","CRISIS")))) -> ELEVATED | T24: =IF(C24="","-",IF(C24<15,"EQUITY TREND",IF(C24<25,"NORMAL",IF(C24<35,"ELEVATED",IF(C24<45,"HIGH STRESS","CRISIS"))))) -> NORMAL | U24: =IF(L24="","-",IF(L24<90,"NORMAL",IF(L24<120,"ELEVATED",IF(L24<160,"HIGH STRESS","CRISIS")))) -> NORMAL | V24: =IF(OR(C24="",L24=""),"-",IF(AND(C24<15,L24<90),"✦ FULL DEPLOYMENT",IF(AND(C24<25,L24<120),"STANDARD OPS",IF(AND(C24<35,L24<160),"REDUCE / BUILD LIST",IF(AND(C24<45,L24<160),"QUALITY ONLY","MAX CASH / WAIT"))))) -> STANDARD OPS | W24: =IF(OR(C24="",L24=""),"-",IF(AND(C24<15,L24<90),"HOLD",IF(AND(C24<25,L24<120),"MONITOR",IF(AND(C24>=25,C24<35),"WAIT — DEFENSIVE",IF(C24>=35,"STRONG BUY","HOLD"))))) -> MONITOR | Y24: =IF(C24="","-",IF(C24<C23,IF(Y23="-",1,Y23+1),0)) -> 0 | Z24: =IF(OR(C24="",L24="",P24=""),"-",IF(AND(C24<25,L24<95,P24<30,Y24>=3),"🟢 REVERSION WATCH",IF(AND(C24<27,L24<105,P24<35,Y24>=2),"🟡 APPROACHING","🔴 NOT YET"))) -> 🔴 NOT YET | AA24: 31 | AB24: 82
B25: 46119 | C25: 25.78 | D25: =IF(OR(C25="",C24=""),"-",C25-C24) -> 1.61 | E25: 23.95 | F25: 23.37 | G25: 23.15 | H25: - | I25: =IF(C25="","-",IF(E25<>"",C25-E25,IF(F25<>"",C25-F25,IF(G25<>"",C25-G25,IF(H25<>"",C25-H25,"-"))))) -> 1.83 | J25: =IF(C25="","-",IF(E25<>"",IF(F25<>"",C25-F25,IF(G25<>"",C25-G25,IF(H25<>"",C25-H25,"-"))),IF(F25<>"",IF(G25<>"",C25-G25,IF(H25<>"",C25-H25,"-")),IF(G25<>"",IF(H25<>"",C25-H25,"-"),"-")))) -> 2.41 | L25: 83.15 | M25: =IF(OR(L25="",L24=""),"-",L25-L24) -> 1.47 | N25: =IF(OR(L25="",L24=""),"-",(L25-L24)/L24) -> 0.017997062 | P25: 25.7 | Q25: =IF(OR(P25="",P24=""),"-",P25-P24) -> 1.62 | R25: =IF(OR(P25="",P24=""),"-",(P25-P24)/P24) -> 0.067275748 | S25: =IF(P25="","-",IF(P25<20,"CALM",IF(P25<40,"ELEVATED",IF(P25<60,"STRESSED","CRISIS")))) -> ELEVATED | T25: =IF(C25="","-",IF(C25<15,"EQUITY TREND",IF(C25<25,"NORMAL",IF(C25<35,"ELEVATED",IF(C25<45,"HIGH STRESS","CRISIS"))))) -> ELEVATED | U25: =IF(L25="","-",IF(L25<90,"NORMAL",IF(L25<120,"ELEVATED",IF(L25<160,"HIGH STRESS","CRISIS")))) -> NORMAL | V25: =IF(OR(C25="",L25=""),"-",IF(AND(C25<15,L25<90),"✦ FULL DEPLOYMENT",IF(AND(C25<25,L25<120),"STANDARD OPS",IF(AND(C25<35,L25<160),"REDUCE / BUILD LIST",IF(AND(C25<45,L25<160),"QUALITY ONLY","MAX CASH / WAIT"))))) -> REDUCE / BUILD LIST | W25: =IF(OR(C25="",L25=""),"-",IF(AND(C25<15,L25<90),"HOLD",IF(AND(C25<25,L25<120),"MONITOR",IF(AND(C25>=25,C25<35),"WAIT — DEFENSIVE",IF(C25>=35,"STRONG BUY","HOLD"))))) -> WAIT — DEFENSIVE | Y25: =IF(C25="","-",IF(C25<C24,IF(Y24="-",1,Y24+1),0)) -> 0 | Z25: =IF(OR(C25="",L25="",P25=""),"-",IF(AND(C25<25,L25<95,P25<30,Y25>=3),"🟢 REVERSION WATCH",IF(AND(C25<27,L25<105,P25<35,Y25>=2),"🟡 APPROACHING","🔴 NOT YET"))) -> 🔴 NOT YET | AA25: 29 | AB25: 66
B26: 46120 | C26: 21.04 | D26: =IF(OR(C26="",C25=""),"-",C26-C25) -> -4.74 | E26: 22 | F26: 22.15 | G26: 22.22 | H26: - | I26: =IF(C26="","-",IF(E26<>"",C26-E26,IF(F26<>"",C26-F26,IF(G26<>"",C26-G26,IF(H26<>"",C26-H26,"-"))))) -> -0.96 | J26: =IF(C26="","-",IF(E26<>"",IF(F26<>"",C26-F26,IF(G26<>"",C26-G26,IF(H26<>"",C26-H26,"-"))),IF(F26<>"",IF(G26<>"",C26-G26,IF(H26<>"",C26-H26,"-")),IF(G26<>"",IF(H26<>"",C26-H26,"-"),"-")))) -> -1.11 | L26: 78.74 | M26: =IF(OR(L26="",L25=""),"-",L26-L25) -> -4.41 | N26: =IF(OR(L26="",L25=""),"-",(L26-L25)/L25) -> -0.053036681 | P26: 17.27 | Q26: =IF(OR(P26="",P25=""),"-",P26-P25) -> -8.43 | R26: =IF(OR(P26="",P25=""),"-",(P26-P25)/P25) -> -0.32801556 | S26: =IF(P26="","-",IF(P26<20,"CALM",IF(P26<40,"ELEVATED",IF(P26<60,"STRESSED","CRISIS")))) -> CALM | T26: =IF(C26="","-",IF(C26<15,"EQUITY TREND",IF(C26<25,"NORMAL",IF(C26<35,"ELEVATED",IF(C26<45,"HIGH STRESS","CRISIS"))))) -> NORMAL | U26: =IF(L26="","-",IF(L26<90,"NORMAL",IF(L26<120,"ELEVATED",IF(L26<160,"HIGH STRESS","CRISIS")))) -> NORMAL | V26: =IF(OR(C26="",L26=""),"-",IF(AND(C26<15,L26<90),"✦ FULL DEPLOYMENT",IF(AND(C26<25,L26<120),"STANDARD OPS",IF(AND(C26<35,L26<160),"REDUCE / BUILD LIST",IF(AND(C26<45,L26<160),"QUALITY ONLY","MAX CASH / WAIT"))))) -> STANDARD OPS | W26: =IF(OR(C26="",L26=""),"-",IF(AND(C26<15,L26<90),"HOLD",IF(AND(C26<25,L26<120),"MONITOR",IF(AND(C26>=25,C26<35),"WAIT — DEFENSIVE",IF(C26>=35,"STRONG BUY","HOLD"))))) -> MONITOR | Y26: =IF(C26="","-",IF(C26<C25,IF(Y25="-",1,Y25+1),0)) -> 1 | Z26: =IF(OR(C26="",L26="",P26=""),"-",IF(AND(C26<25,L26<95,P26<30,Y26>=3),"🟢 REVERSION WATCH",IF(AND(C26<27,L26<105,P26<35,Y26>=2),"🟡 APPROACHING","🔴 NOT YET"))) -> 🔴 NOT YET | AA26: 46 | AB26: 152
B27: 46121 | C27: 19.49 | D27: =IF(OR(C27="",C26=""),"-",C27-C26) -> -1.55 | E27: 20.28 | F27: 21.22 | G27: 21.6 | H27: 22.11 | I27: =IF(C27="","-",IF(E27<>"",C27-E27,IF(F27<>"",C27-F27,IF(G27<>"",C27-G27,IF(H27<>"",C27-H27,"-"))))) -> -0.79 | J27: =IF(C27="","-",IF(E27<>"",IF(F27<>"",C27-F27,IF(G27<>"",C27-G27,IF(H27<>"",C27-H27,"-"))),IF(F27<>"",IF(G27<>"",C27-G27,IF(H27<>"",C27-H27,"-")),IF(G27<>"",IF(H27<>"",C27-H27,"-"),"-")))) -> -1.73 | L27: 74.01 | M27: =IF(OR(L27="",L26=""),"-",L27-L26) -> -4.73 | N27: =IF(OR(L27="",L26=""),"-",(L27-L26)/L26) -> -0.06007112 | P27: 14.25 | Q27: =IF(OR(P27="",P26=""),"-",P27-P26) -> -3.02 | R27: =IF(OR(P27="",P26=""),"-",(P27-P26)/P26) -> -0.17486972 | S27: =IF(P27="","-",IF(P27<20,"CALM",IF(P27<40,"ELEVATED",IF(P27<60,"STRESSED","CRISIS")))) -> CALM | T27: =IF(C27="","-",IF(C27<15,"EQUITY TREND",IF(C27<25,"NORMAL",IF(C27<35,"ELEVATED",IF(C27<45,"HIGH STRESS","CRISIS"))))) -> NORMAL | U27: =IF(L27="","-",IF(L27<90,"NORMAL",IF(L27<120,"ELEVATED",IF(L27<160,"HIGH STRESS","CRISIS")))) -> NORMAL | V27: =IF(OR(C27="",L27=""),"-",IF(AND(C27<15,L27<90),"✦ FULL DEPLOYMENT",IF(AND(C27<25,L27<120),"STANDARD OPS",IF(AND(C27<35,L27<160),"REDUCE / BUILD LIST",IF(AND(C27<45,L27<160),"QUALITY ONLY","MAX CASH / WAIT"))))) -> STANDARD OPS | W27: =IF(OR(C27="",L27=""),"-",IF(AND(C27<15,L27<90),"HOLD",IF(AND(C27<25,L27<120),"MONITOR",IF(AND(C27>=25,C27<35),"WAIT — DEFENSIVE",IF(C27>=35,"STRONG BUY","HOLD"))))) -> MONITOR | Y27: =IF(C27="","-",IF(C27<C26,IF(Y26="-",1,Y26+1),0)) -> 2 | Z27: =IF(OR(C27="",L27="",P27=""),"-",IF(AND(C27<25,L27<95,P27<30,Y27>=3),"🟢 REVERSION WATCH",IF(AND(C27<27,L27<105,P27<35,Y27>=2),"🟡 APPROACHING","🔴 NOT YET"))) -> 🟡 APPROACHING | AA27: 48 | AB27: 170
B28: 46122 | C28: 19.29 | D28: =IF(OR(C28="",C27=""),"-",C28-C27) -> -0.2 | E28: 20.36 | F28: 21.47 | G28: 21.82 | H28: 22.23 | I28: =IF(C28="","-",IF(E28<>"",C28-E28,IF(F28<>"",C28-F28,IF(G28<>"",C28-G28,IF(H28<>"",C28-H28,"-"))))) -> -1.07 | J28: =IF(C28="","-",IF(E28<>"",IF(F28<>"",C28-F28,IF(G28<>"",C28-G28,IF(H28<>"",C28-H28,"-"))),IF(F28<>"",IF(G28<>"",C28-G28,IF(H28<>"",C28-H28,"-")),IF(G28<>"",IF(H28<>"",C28-H28,"-"),"-")))) -> -2.18 | L28: 72.15 | M28: =IF(OR(L28="",L27=""),"-",L28-L27) -> -1.86 | N28: =IF(OR(L28="",L27=""),"-",(L28-L27)/L27) -> -0.025131739 | P28: 13.6 | Q28: =IF(OR(P28="",P27=""),"-",P28-P27) -> -0.65 | R28: =IF(OR(P28="",P27=""),"-",(P28-P27)/P27) -> -0.045614035 | S28: =IF(P28="","-",IF(P28<20,"CALM",IF(P28<40,"ELEVATED",IF(P28<60,"STRESSED","CRISIS")))) -> CALM | T28: =IF(C28="","-",IF(C28<15,"EQUITY TREND",IF(C28<25,"NORMAL",IF(C28<35,"ELEVATED",IF(C28<45,"HIGH STRESS","CRISIS"))))) -> NORMAL | U28: =IF(L28="","-",IF(L28<90,"NORMAL",IF(L28<120,"ELEVATED",IF(L28<160,"HIGH STRESS","CRISIS")))) -> NORMAL | V28: =IF(OR(C28="",L28=""),"-",IF(AND(C28<15,L28<90),"✦ FULL DEPLOYMENT",IF(AND(C28<25,L28<120),"STANDARD OPS",IF(AND(C28<35,L28<160),"REDUCE / BUILD LIST",IF(AND(C28<45,L28<160),"QUALITY ONLY","MAX CASH / WAIT"))))) -> STANDARD OPS | W28: =IF(OR(C28="",L28=""),"-",IF(AND(C28<15,L28<90),"HOLD",IF(AND(C28<25,L28<120),"MONITOR",IF(AND(C28>=25,C28<35),"WAIT — DEFENSIVE",IF(C28>=35,"STRONG BUY","HOLD"))))) -> MONITOR | Y28: =IF(C28="","-",IF(C28<C27,IF(Y27="-",1,Y27+1),0)) -> 3 | Z28: =IF(OR(C28="",L28="",P28=""),"-",IF(AND(C28<25,L28<95,P28<30,Y28>=3),"🟢 REVERSION WATCH",IF(AND(C28<27,L28<105,P28<35,Y28>=2),"🟡 APPROACHING","🔴 NOT YET"))) -> 🟢 REVERSION WATCH | AA28: 43 | AB28: 132
D29: =IF(OR(C29="",C28=""),"-",C29-C28) -> - | I29: =IF(C29="","-",IF(E29<>"",C29-E29,IF(F29<>"",C29-F29,IF(G29<>"",C29-G29,IF(H29<>"",C29-H29,"-"))))) -> - | J29: =IF(C29="","-",IF(E29<>"",IF(F29<>"",C29-F29,IF(G29<>"",C29-G29,IF(H29<>"",C29-H29,"-"))),IF(F29<>"",IF(G29<>"",C29-G29,IF(H29<>"",C29-H29,"-")),IF(G29<>"",IF(H29<>"",C29-H29,"-"),"-")))) -> - | M29: =IF(OR(L29="",L28=""),"-",L29-L28) -> - | N29: =IF(OR(L29="",L28=""),"-",(L29-L28)/L28) -> - | Q29: =IF(OR(P29="",P28=""),"-",P29-P28) -> - | R29: =IF(OR(P29="",P28=""),"-",(P29-P28)/P28) -> - | S29: =IF(P29="","-",IF(P29<20,"CALM",IF(P29<40,"ELEVATED",IF(P29<60,"STRESSED","CRISIS")))) -> - | T29: =IF(C29="","-",IF(C29<15,"EQUITY TREND",IF(C29<25,"NORMAL",IF(C29<35,"ELEVATED",IF(C29<45,"HIGH STRESS","CRISIS"))))) -> - | U29: =IF(L29="","-",IF(L29<90,"NORMAL",IF(L29<120,"ELEVATED",IF(L29<160,"HIGH STRESS","CRISIS")))) -> - | V29: =IF(OR(C29="",L29=""),"-",IF(AND(C29<15,L29<90),"✦ FULL DEPLOYMENT",IF(AND(C29<25,L29<120),"STANDARD OPS",IF(AND(C29<35,L29<160),"REDUCE / BUILD LIST",IF(AND(C29<45,L29<160),"QUALITY ONLY","MAX CASH / WAIT"))))) -> - | W29: =IF(OR(C29="",L29=""),"-",IF(AND(C29<15,L29<90),"HOLD",IF(AND(C29<25,L29<120),"MONITOR",IF(AND(C29>=25,C29<35),"WAIT — DEFENSIVE",IF(C29>=35,"STRONG BUY","HOLD"))))) -> - | Y29: =IF(C29="","-",IF(C29<C28,IF(Y28="-",1,Y28+1),0)) -> - | Z29: =IF(OR(C29="",L29="",P29=""),"-",IF(AND(C29<25,L29<95,P29<30,Y29>=3),"🟢 REVERSION WATCH",IF(AND(C29<27,L29<105,P29<35,Y29>=2),"🟡 APPROACHING","🔴 NOT YET"))) -> -
D30: =IF(OR(C30="",C29=""),"-",C30-C29) -> - | I30: =IF(C30="","-",IF(E30<>"",C30-E30,IF(F30<>"",C30-F30,IF(G30<>"",C30-G30,IF(H30<>"",C30-H30,"-"))))) -> - | J30: =IF(C30="","-",IF(E30<>"",IF(F30<>"",C30-F30,IF(G30<>"",C30-G30,IF(H30<>"",C30-H30,"-"))),IF(F30<>"",IF(G30<>"",C30-G30,IF(H30<>"",C30-H30,"-")),IF(G30<>"",IF(H30<>"",C30-H30,"-"),"-")))) -> - | M30: =IF(OR(L30="",L29=""),"-",L30-L29) -> - | N30: =IF(OR(L30="",L29=""),"-",(L30-L29)/L29) -> - | Q30: =IF(OR(P30="",P29=""),"-",P30-P29) -> - | R30: =IF(OR(P30="",P29=""),"-",(P30-P29)/P29) -> - | S30: =IF(P30="","-",IF(P30<20,"CALM",IF(P30<40,"ELEVATED",IF(P30<60,"STRESSED","CRISIS")))) -> - | T30: =IF(C30="","-",IF(C30<15,"EQUITY TREND",IF(C30<25,"NORMAL",IF(C30<35,"ELEVATED",IF(C30<45,"HIGH STRESS","CRISIS"))))) -> - | U30: =IF(L30="","-",IF(L30<90,"NORMAL",IF(L30<120,"ELEVATED",IF(L30<160,"HIGH STRESS","CRISIS")))) -> - | V30: =IF(OR(C30="",L30=""),"-",IF(AND(C30<15,L30<90),"✦ FULL DEPLOYMENT",IF(AND(C30<25,L30<120),"STANDARD OPS",IF(AND(C30<35,L30<160),"REDUCE / BUILD LIST",IF(AND(C30<45,L30<160),"QUALITY ONLY","MAX CASH / WAIT"))))) -> - | W30: =IF(OR(C30="",L30=""),"-",IF(AND(C30<15,L30<90),"HOLD",IF(AND(C30<25,L30<120),"MONITOR",IF(AND(C30>=25,C30<35),"WAIT — DEFENSIVE",IF(C30>=35,"STRONG BUY","HOLD"))))) -> - | Y30: =IF(C30="","-",IF(C30<C29,IF(Y29="-",1,Y29+1),0)) -> - | Z30: =IF(OR(C30="",L30="",P30=""),"-",IF(AND(C30<25,L30<95,P30<30,Y30>=3),"🟢 REVERSION WATCH",IF(AND(C30<27,L30<105,P30<35,Y30>=2),"🟡 APPROACHING","🔴 NOT YET"))) -> -
D31: =IF(OR(C31="",C30=""),"-",C31-C30) -> - | I31: =IF(C31="","-",IF(E31<>"",C31-E31,IF(F31<>"",C31-F31,IF(G31<>"",C31-G31,IF(H31<>"",C31-H31,"-"))))) -> - | J31: =IF(C31="","-",IF(E31<>"",IF(F31<>"",C31-F31,IF(G31<>"",C31-G31,IF(H31<>"",C31-H31,"-"))),IF(F31<>"",IF(G31<>"",C31-G31,IF(H31<>"",C31-H31,"-")),IF(G31<>"",IF(H31<>"",C31-H31,"-"),"-")))) -> - | M31: =IF(OR(L31="",L30=""),"-",L31-L30) -> - | N31: =IF(OR(L31="",L30=""),"-",(L31-L30)/L30) -> - | Q31: =IF(OR(P31="",P30=""),"-",P31-P30) -> - | R31: =IF(OR(P31="",P30=""),"-",(P31-P30)/P30) -> - | S31: =IF(P31="","-",IF(P31<20,"CALM",IF(P31<40,"ELEVATED",IF(P31<60,"STRESSED","CRISIS")))) -> - | T31: =IF(C31="","-",IF(C31<15,"EQUITY TREND",IF(C31<25,"NORMAL",IF(C31<35,"ELEVATED",IF(C31<45,"HIGH STRESS","CRISIS"))))) -> - | U31: =IF(L31="","-",IF(L31<90,"NORMAL",IF(L31<120,"ELEVATED",IF(L31<160,"HIGH STRESS","CRISIS")))) -> - | V31: =IF(OR(C31="",L31=""),"-",IF(AND(C31<15,L31<90),"✦ FULL DEPLOYMENT",IF(AND(C31<25,L31<120),"STANDARD OPS",IF(AND(C31<35,L31<160),"REDUCE / BUILD LIST",IF(AND(C31<45,L31<160),"QUALITY ONLY","MAX CASH / WAIT"))))) -> - | W31: =IF(OR(C31="",L31=""),"-",IF(AND(C31<15,L31<90),"HOLD",IF(AND(C31<25,L31<120),"MONITOR",IF(AND(C31>=25,C31<35),"WAIT — DEFENSIVE",IF(C31>=35,"STRONG BUY","HOLD"))))) -> - | Y31: =IF(C31="","-",IF(C31<C30,IF(Y30="-",1,Y30+1),0)) -> - | Z31: =IF(OR(C31="",L31="",P31=""),"-",IF(AND(C31<25,L31<95,P31<30,Y31>=3),"🟢 REVERSION WATCH",IF(AND(C31<27,L31<105,P31<35,Y31>=2),"🟡 APPROACHING","🔴 NOT YET"))) -> -
D32: =IF(OR(C32="",C31=""),"-",C32-C31) -> - | I32: =IF(C32="","-",IF(E32<>"",C32-E32,IF(F32<>"",C32-F32,IF(G32<>"",C32-G32,IF(H32<>"",C32-H32,"-"))))) -> - | J32: =IF(C32="","-",IF(E32<>"",IF(F32<>"",C32-F32,IF(G32<>"",C32-G32,IF(H32<>"",C32-H32,"-"))),IF(F32<>"",IF(G32<>"",C32-G32,IF(H32<>"",C32-H32,"-")),IF(G32<>"",IF(H32<>"",C32-H32,"-"),"-")))) -> - | M32: =IF(OR(L32="",L31=""),"-",L32-L31) -> - | N32: =IF(OR(L32="",L31=""),"-",(L32-L31)/L31) -> - | Q32: =IF(OR(P32="",P31=""),"-",P32-P31) -> - | R32: =IF(OR(P32="",P31=""),"-",(P32-P31)/P31) -> - | S32: =IF(P32="","-",IF(P32<20,"CALM",IF(P32<40,"ELEVATED",IF(P32<60,"STRESSED","CRISIS")))) -> - | T32: =IF(C32="","-",IF(C32<15,"EQUITY TREND",IF(C32<25,"NORMAL",IF(C32<35,"ELEVATED",IF(C32<45,"HIGH STRESS","CRISIS"))))) -> - | U32: =IF(L32="","-",IF(L32<90,"NORMAL",IF(L32<120,"ELEVATED",IF(L32<160,"HIGH STRESS","CRISIS")))) -> - | V32: =IF(OR(C32="",L32=""),"-",IF(AND(C32<15,L32<90),"✦ FULL DEPLOYMENT",IF(AND(C32<25,L32<120),"STANDARD OPS",IF(AND(C32<35,L32<160),"REDUCE / BUILD LIST",IF(AND(C32<45,L32<160),"QUALITY ONLY","MAX CASH / WAIT"))))) -> - | W32: =IF(OR(C32="",L32=""),"-",IF(AND(C32<15,L32<90),"HOLD",IF(AND(C32<25,L32<120),"MONITOR",IF(AND(C32>=25,C32<35),"WAIT — DEFENSIVE",IF(C32>=35,"STRONG BUY","HOLD"))))) -> - | Y32: =IF(C32="","-",IF(C32<C31,IF(Y31="-",1,Y31+1),0)) -> - | Z32: =IF(OR(C32="",L32="",P32=""),"-",IF(AND(C32<25,L32<95,P32<30,Y32>=3),"🟢 REVERSION WATCH",IF(AND(C32<27,L32<105,P32<35,Y32>=2),"🟡 APPROACHING","🔴 NOT YET"))) -> -
D33: =IF(OR(C33="",C32=""),"-",C33-C32) -> - | I33: =IF(C33="","-",IF(E33<>"",C33-E33,IF(F33<>"",C33-F33,IF(G33<>"",C33-G33,IF(H33<>"",C33-H33,"-"))))) -> - | J33: =IF(C33="","-",IF(E33<>"",IF(F33<>"",C33-F33,IF(G33<>"",C33-G33,IF(H33<>"",C33-H33,"-"))),IF(F33<>"",IF(G33<>"",C33-G33,IF(H33<>"",C33-H33,"-")),IF(G33<>"",IF(H33<>"",C33-H33,"-"),"-")))) -> - | M33: =IF(OR(L33="",L32=""),"-",L33-L32) -> - | N33: =IF(OR(L33="",L32=""),"-",(L33-L32)/L32) -> - | Q33: =IF(OR(P33="",P32=""),"-",P33-P32) -> - | R33: =IF(OR(P33="",P32=""),"-",(P33-P32)/P32) -> - | S33: =IF(P33="","-",IF(P33<20,"CALM",IF(P33<40,"ELEVATED",IF(P33<60,"STRESSED","CRISIS")))) -> - | T33: =IF(C33="","-",IF(C33<15,"EQUITY TREND",IF(C33<25,"NORMAL",IF(C33<35,"ELEVATED",IF(C33<45,"HIGH STRESS","CRISIS"))))) -> - | U33: =IF(L33="","-",IF(L33<90,"NORMAL",IF(L33<120,"ELEVATED",IF(L33<160,"HIGH STRESS","CRISIS")))) -> - | V33: =IF(OR(C33="",L33=""),"-",IF(AND(C33<15,L33<90),"✦ FULL DEPLOYMENT",IF(AND(C33<25,L33<120),"STANDARD OPS",IF(AND(C33<35,L33<160),"REDUCE / BUILD LIST",IF(AND(C33<45,L33<160),"QUALITY ONLY","MAX CASH / WAIT"))))) -> - | W33: =IF(OR(C33="",L33=""),"-",IF(AND(C33<15,L33<90),"HOLD",IF(AND(C33<25,L33<120),"MONITOR",IF(AND(C33>=25,C33<35),"WAIT — DEFENSIVE",IF(C33>=35,"STRONG BUY","HOLD"))))) -> - | Y33: =IF(C33="","-",IF(C33<C32,IF(Y32="-",1,Y32+1),0)) -> - | Z33: =IF(OR(C33="",L33="",P33=""),"-",IF(AND(C33<25,L33<95,P33<30,Y33>=3),"🟢 REVERSION WATCH",IF(AND(C33<27,L33<105,P33<35,Y33>=2),"🟡 APPROACHING","🔴 NOT YET"))) -> -
D34: =IF(OR(C34="",C33=""),"-",C34-C33) -> - | I34: =IF(C34="","-",IF(E34<>"",C34-E34,IF(F34<>"",C34-F34,IF(G34<>"",C34-G34,IF(H34<>"",C34-H34,"-"))))) -> - | J34: =IF(C34="","-",IF(E34<>"",IF(F34<>"",C34-F34,IF(G34<>"",C34-G34,IF(H34<>"",C34-H34,"-"))),IF(F34<>"",IF(G34<>"",C34-G34,IF(H34<>"",C34-H34,"-")),IF(G34<>"",IF(H34<>"",C34-H34,"-"),"-")))) -> - | M34: =IF(OR(L34="",L33=""),"-",L34-L33) -> - | N34: =IF(OR(L34="",L33=""),"-",(L34-L33)/L33) -> - | Q34: =IF(OR(P34="",P33=""),"-",P34-P33) -> - | R34: =IF(OR(P34="",P33=""),"-",(P34-P33)/P33) -> - | S34: =IF(P34="","-",IF(P34<20,"CALM",IF(P34<40,"ELEVATED",IF(P34<60,"STRESSED","CRISIS")))) -> - | T34: =IF(C34="","-",IF(C34<15,"EQUITY TREND",IF(C34<25,"NORMAL",IF(C34<35,"ELEVATED",IF(C34<45,"HIGH STRESS","CRISIS"))))) -> - | U34: =IF(L34="","-",IF(L34<90,"NORMAL",IF(L34<120,"ELEVATED",IF(L34<160,"HIGH STRESS","CRISIS")))) -> - | V34: =IF(OR(C34="",L34=""),"-",IF(AND(C34<15,L34<90),"✦ FULL DEPLOYMENT",IF(AND(C34<25,L34<120),"STANDARD OPS",IF(AND(C34<35,L34<160),"REDUCE / BUILD LIST",IF(AND(C34<45,L34<160),"QUALITY ONLY","MAX CASH / WAIT"))))) -> - | W34: =IF(OR(C34="",L34=""),"-",IF(AND(C34<15,L34<90),"HOLD",IF(AND(C34<25,L34<120),"MONITOR",IF(AND(C34>=25,C34<35),"WAIT — DEFENSIVE",IF(C34>=35,"STRONG BUY","HOLD"))))) -> - | Y34: =IF(C34="","-",IF(C34<C33,IF(Y33="-",1,Y33+1),0)) -> - | Z34: =IF(OR(C34="",L34="",P34=""),"-",IF(AND(C34<25,L34<95,P34<30,Y34>=3),"🟢 REVERSION WATCH",IF(AND(C34<27,L34<105,P34<35,Y34>=2),"🟡 APPROACHING","🔴 NOT YET"))) -> -
D35: =IF(OR(C35="",C34=""),"-",C35-C34) -> - | I35: =IF(C35="","-",IF(E35<>"",C35-E35,IF(F35<>"",C35-F35,IF(G35<>"",C35-G35,IF(H35<>"",C35-H35,"-"))))) -> - | J35: =IF(C35="","-",IF(E35<>"",IF(F35<>"",C35-F35,IF(G35<>"",C35-G35,IF(H35<>"",C35-H35,"-"))),IF(F35<>"",IF(G35<>"",C35-G35,IF(H35<>"",C35-H35,"-")),IF(G35<>"",IF(H35<>"",C35-H35,"-"),"-")))) -> - | M35: =IF(OR(L35="",L34=""),"-",L35-L34) -> - | N35: =IF(OR(L35="",L34=""),"-",(L35-L34)/L34) -> - | Q35: =IF(OR(P35="",P34=""),"-",P35-P34) -> - | R35: =IF(OR(P35="",P34=""),"-",(P35-P34)/P34) -> - | S35: =IF(P35="","-",IF(P35<20,"CALM",IF(P35<40,"ELEVATED",IF(P35<60,"STRESSED","CRISIS")))) -> - | T35: =IF(C35="","-",IF(C35<15,"EQUITY TREND",IF(C35<25,"NORMAL",IF(C35<35,"ELEVATED",IF(C35<45,"HIGH STRESS","CRISIS"))))) -> - | U35: =IF(L35="","-",IF(L35<90,"NORMAL",IF(L35<120,"ELEVATED",IF(L35<160,"HIGH STRESS","CRISIS")))) -> - | V35: =IF(OR(C35="",L35=""),"-",IF(AND(C35<15,L35<90),"✦ FULL DEPLOYMENT",IF(AND(C35<25,L35<120),"STANDARD OPS",IF(AND(C35<35,L35<160),"REDUCE / BUILD LIST",IF(AND(C35<45,L35<160),"QUALITY ONLY","MAX CASH / WAIT"))))) -> - | W35: =IF(OR(C35="",L35=""),"-",IF(AND(C35<15,L35<90),"HOLD",IF(AND(C35<25,L35<120),"MONITOR",IF(AND(C35>=25,C35<35),"WAIT — DEFENSIVE",IF(C35>=35,"STRONG BUY","HOLD"))))) -> - | Y35: =IF(C35="","-",IF(C35<C34,IF(Y34="-",1,Y34+1),0)) -> - | Z35: =IF(OR(C35="",L35="",P35=""),"-",IF(AND(C35<25,L35<95,P35<30,Y35>=3),"🟢 REVERSION WATCH",IF(AND(C35<27,L35<105,P35<35,Y35>=2),"🟡 APPROACHING","🔴 NOT YET"))) -> -
D36: =IF(OR(C36="",C35=""),"-",C36-C35) -> - | I36: =IF(C36="","-",IF(E36<>"",C36-E36,IF(F36<>"",C36-F36,IF(G36<>"",C36-G36,IF(H36<>"",C36-H36,"-"))))) -> - | J36: =IF(C36="","-",IF(E36<>"",IF(F36<>"",C36-F36,IF(G36<>"",C36-G36,IF(H36<>"",C36-H36,"-"))),IF(F36<>"",IF(G36<>"",C36-G36,IF(H36<>"",C36-H36,"-")),IF(G36<>"",IF(H36<>"",C36-H36,"-"),"-")))) -> - | M36: =IF(OR(L36="",L35=""),"-",L36-L35) -> - | N36: =IF(OR(L36="",L35=""),"-",(L36-L35)/L35) -> - | Q36: =IF(OR(P36="",P35=""),"-",P36-P35) -> - | R36: =IF(OR(P36="",P35=""),"-",(P36-P35)/P35) -> - | S36: =IF(P36="","-",IF(P36<20,"CALM",IF(P36<40,"ELEVATED",IF(P36<60,"STRESSED","CRISIS")))) -> - | T36: =IF(C36="","-",IF(C36<15,"EQUITY TREND",IF(C36<25,"NORMAL",IF(C36<35,"ELEVATED",IF(C36<45,"HIGH STRESS","CRISIS"))))) -> - | U36: =IF(L36="","-",IF(L36<90,"NORMAL",IF(L36<120,"ELEVATED",IF(L36<160,"HIGH STRESS","CRISIS")))) -> - | V36: =IF(OR(C36="",L36=""),"-",IF(AND(C36<15,L36<90),"✦ FULL DEPLOYMENT",IF(AND(C36<25,L36<120),"STANDARD OPS",IF(AND(C36<35,L36<160),"REDUCE / BUILD LIST",IF(AND(C36<45,L36<160),"QUALITY ONLY","MAX CASH / WAIT"))))) -> - | W36: =IF(OR(C36="",L36=""),"-",IF(AND(C36<15,L36<90),"HOLD",IF(AND(C36<25,L36<120),"MONITOR",IF(AND(C36>=25,C36<35),"WAIT — DEFENSIVE",IF(C36>=35,"STRONG BUY","HOLD"))))) -> - | Y36: =IF(C36="","-",IF(C36<C35,IF(Y35="-",1,Y35+1),0)) -> - | Z36: =IF(OR(C36="",L36="",P36=""),"-",IF(AND(C36<25,L36<95,P36<30,Y36>=3),"🟢 REVERSION WATCH",IF(AND(C36<27,L36<105,P36<35,Y36>=2),"🟡 APPROACHING","🔴 NOT YET"))) -> -
D37: =IF(OR(C37="",C36=""),"-",C37-C36) -> - | I37: =IF(C37="","-",IF(E37<>"",C37-E37,IF(F37<>"",C37-F37,IF(G37<>"",C37-G37,IF(H37<>"",C37-H37,"-"))))) -> - | J37: =IF(C37="","-",IF(E37<>"",IF(F37<>"",C37-F37,IF(G37<>"",C37-G37,IF(H37<>"",C37-H37,"-"))),IF(F37<>"",IF(G37<>"",C37-G37,IF(H37<>"",C37-H37,"-")),IF(G37<>"",IF(H37<>"",C37-H37,"-"),"-")))) -> - | M37: =IF(OR(L37="",L36=""),"-",L37-L36) -> - | N37: =IF(OR(L37="",L36=""),"-",(L37-L36)/L36) -> - | Q37: =IF(OR(P37="",P36=""),"-",P37-P36) -> - | R37: =IF(OR(P37="",P36=""),"-",(P37-P36)/P36) -> - | S37: =IF(P37="","-",IF(P37<20,"CALM",IF(P37<40,"ELEVATED",IF(P37<60,"STRESSED","CRISIS")))) -> - | T37: =IF(C37="","-",IF(C37<15,"EQUITY TREND",IF(C37<25,"NORMAL",IF(C37<35,"ELEVATED",IF(C37<45,"HIGH STRESS","CRISIS"))))) -> - | U37: =IF(L37="","-",IF(L37<90,"NORMAL",IF(L37<120,"ELEVATED",IF(L37<160,"HIGH STRESS","CRISIS")))) -> - | V37: =IF(OR(C37="",L37=""),"-",IF(AND(C37<15,L37<90),"✦ FULL DEPLOYMENT",IF(AND(C37<25,L37<120),"STANDARD OPS",IF(AND(C37<35,L37<160),"REDUCE / BUILD LIST",IF(AND(C37<45,L37<160),"QUALITY ONLY","MAX CASH / WAIT"))))) -> - | W37: =IF(OR(C37="",L37=""),"-",IF(AND(C37<15,L37<90),"HOLD",IF(AND(C37<25,L37<120),"MONITOR",IF(AND(C37>=25,C37<35),"WAIT — DEFENSIVE",IF(C37>=35,"STRONG BUY","HOLD"))))) -> - | Y37: =IF(C37="","-",IF(C37<C36,IF(Y36="-",1,Y36+1),0)) -> - | Z37: =IF(OR(C37="",L37="",P37=""),"-",IF(AND(C37<25,L37<95,P37<30,Y37>=3),"🟢 REVERSION WATCH",IF(AND(C37<27,L37<105,P37<35,Y37>=2),"🟡 APPROACHING","🔴 NOT YET"))) -> -
D38: =IF(OR(C38="",C37=""),"-",C38-C37) -> - | I38: =IF(C38="","-",IF(E38<>"",C38-E38,IF(F38<>"",C38-F38,IF(G38<>"",C38-G38,IF(H38<>"",C38-H38,"-"))))) -> - | J38: =IF(C38="","-",IF(E38<>"",IF(F38<>"",C38-F38,IF(G38<>"",C38-G38,IF(H38<>"",C38-H38,"-"))),IF(F38<>"",IF(G38<>"",C38-G38,IF(H38<>"",C38-H38,"-")),IF(G38<>"",IF(H38<>"",C38-H38,"-"),"-")))) -> - | M38: =IF(OR(L38="",L37=""),"-",L38-L37) -> - | N38: =IF(OR(L38="",L37=""),"-",(L38-L37)/L37) -> - | Q38: =IF(OR(P38="",P37=""),"-",P38-P37) -> - | R38: =IF(OR(P38="",P37=""),"-",(P38-P37)/P37) -> - | S38: =IF(P38="","-",IF(P38<20,"CALM",IF(P38<40,"ELEVATED",IF(P38<60,"STRESSED","CRISIS")))) -> - | T38: =IF(C38="","-",IF(C38<15,"EQUITY TREND",IF(C38<25,"NORMAL",IF(C38<35,"ELEVATED",IF(C38<45,"HIGH STRESS","CRISIS"))))) -> - | U38: =IF(L38="","-",IF(L38<90,"NORMAL",IF(L38<120,"ELEVATED",IF(L38<160,"HIGH STRESS","CRISIS")))) -> - | V38: =IF(OR(C38="",L38=""),"-",IF(AND(C38<15,L38<90),"✦ FULL DEPLOYMENT",IF(AND(C38<25,L38<120),"STANDARD OPS",IF(AND(C38<35,L38<160),"REDUCE / BUILD LIST",IF(AND(C38<45,L38<160),"QUALITY ONLY","MAX CASH / WAIT"))))) -> - | W38: =IF(OR(C38="",L38=""),"-",IF(AND(C38<15,L38<90),"HOLD",IF(AND(C38<25,L38<120),"MONITOR",IF(AND(C38>=25,C38<35),"WAIT — DEFENSIVE",IF(C38>=35,"STRONG BUY","HOLD"))))) -> - | Y38: =IF(C38="","-",IF(C38<C37,IF(Y37="-",1,Y37+1),0)) -> - | Z38: =IF(OR(C38="",L38="",P38=""),"-",IF(AND(C38<25,L38<95,P38<30,Y38>=3),"🟢 REVERSION WATCH",IF(AND(C38<27,L38<105,P38<35,Y38>=2),"🟡 APPROACHING","🔴 NOT YET"))) -> -
D39: =IF(OR(C39="",C38=""),"-",C39-C38) -> - | I39: =IF(C39="","-",IF(E39<>"",C39-E39,IF(F39<>"",C39-F39,IF(G39<>"",C39-G39,IF(H39<>"",C39-H39,"-"))))) -> - | J39: =IF(C39="","-",IF(E39<>"",IF(F39<>"",C39-F39,IF(G39<>"",C39-G39,IF(H39<>"",C39-H39,"-"))),IF(F39<>"",IF(G39<>"",C39-G39,IF(H39<>"",C39-H39,"-")),IF(G39<>"",IF(H39<>"",C39-H39,"-"),"-")))) -> - | M39: =IF(OR(L39="",L38=""),"-",L39-L38) -> - | N39: =IF(OR(L39="",L38=""),"-",(L39-L38)/L38) -> - | Q39: =IF(OR(P39="",P38=""),"-",P39-P38) -> - | R39: =IF(OR(P39="",P38=""),"-",(P39-P38)/P38) -> - | S39: =IF(P39="","-",IF(P39<20,"CALM",IF(P39<40,"ELEVATED",IF(P39<60,"STRESSED","CRISIS")))) -> - | T39: =IF(C39="","-",IF(C39<15,"EQUITY TREND",IF(C39<25,"NORMAL",IF(C39<35,"ELEVATED",IF(C39<45,"HIGH STRESS","CRISIS"))))) -> - | U39: =IF(L39="","-",IF(L39<90,"NORMAL",IF(L39<120,"ELEVATED",IF(L39<160,"HIGH STRESS","CRISIS")))) -> - | V39: =IF(OR(C39="",L39=""),"-",IF(AND(C39<15,L39<90),"✦ FULL DEPLOYMENT",IF(AND(C39<25,L39<120),"STANDARD OPS",IF(AND(C39<35,L39<160),"REDUCE / BUILD LIST",IF(AND(C39<45,L39<160),"QUALITY ONLY","MAX CASH / WAIT"))))) -> - | W39: =IF(OR(C39="",L39=""),"-",IF(AND(C39<15,L39<90),"HOLD",IF(AND(C39<25,L39<120),"MONITOR",IF(AND(C39>=25,C39<35),"WAIT — DEFENSIVE",IF(C39>=35,"STRONG BUY","HOLD"))))) -> - | Y39: =IF(C39="","-",IF(C39<C38,IF(Y38="-",1,Y38+1),0)) -> - | Z39: =IF(OR(C39="",L39="",P39=""),"-",IF(AND(C39<25,L39<95,P39<30,Y39>=3),"🟢 REVERSION WATCH",IF(AND(C39<27,L39<105,P39<35,Y39>=2),"🟡 APPROACHING","🔴 NOT YET"))) -> -
D40: =IF(OR(C40="",C39=""),"-",C40-C39) -> - | I40: =IF(C40="","-",IF(E40<>"",C40-E40,IF(F40<>"",C40-F40,IF(G40<>"",C40-G40,IF(H40<>"",C40-H40,"-"))))) -> - | J40: =IF(C40="","-",IF(E40<>"",IF(F40<>"",C40-F40,IF(G40<>"",C40-G40,IF(H40<>"",C40-H40,"-"))),IF(F40<>"",IF(G40<>"",C40-G40,IF(H40<>"",C40-H40,"-")),IF(G40<>"",IF(H40<>"",C40-H40,"-"),"-")))) -> - | M40: =IF(OR(L40="",L39=""),"-",L40-L39) -> - | N40: =IF(OR(L40="",L39=""),"-",(L40-L39)/L39) -> - | Q40: =IF(OR(P40="",P39=""),"-",P40-P39) -> - | R40: =IF(OR(P40="",P39=""),"-",(P40-P39)/P39) -> - | S40: =IF(P40="","-",IF(P40<20,"CALM",IF(P40<40,"ELEVATED",IF(P40<60,"STRESSED","CRISIS")))) -> - | T40: =IF(C40="","-",IF(C40<15,"EQUITY TREND",IF(C40<25,"NORMAL",IF(C40<35,"ELEVATED",IF(C40<45,"HIGH STRESS","CRISIS"))))) -> - | U40: =IF(L40="","-",IF(L40<90,"NORMAL",IF(L40<120,"ELEVATED",IF(L40<160,"HIGH STRESS","CRISIS")))) -> - | V40: =IF(OR(C40="",L40=""),"-",IF(AND(C40<15,L40<90),"✦ FULL DEPLOYMENT",IF(AND(C40<25,L40<120),"STANDARD OPS",IF(AND(C40<35,L40<160),"REDUCE / BUILD LIST",IF(AND(C40<45,L40<160),"QUALITY ONLY","MAX CASH / WAIT"))))) -> - | W40: =IF(OR(C40="",L40=""),"-",IF(AND(C40<15,L40<90),"HOLD",IF(AND(C40<25,L40<120),"MONITOR",IF(AND(C40>=25,C40<35),"WAIT — DEFENSIVE",IF(C40>=35,"STRONG BUY","HOLD"))))) -> - | Y40: =IF(C40="","-",IF(C40<C39,IF(Y39="-",1,Y39+1),0)) -> - | Z40: =IF(OR(C40="",L40="",P40=""),"-",IF(AND(C40<25,L40<95,P40<30,Y40>=3),"🟢 REVERSION WATCH",IF(AND(C40<27,L40<105,P40<35,Y40>=2),"🟡 APPROACHING","🔴 NOT YET"))) -> -
...

Sheet Regime Reference
B1: REGIME REFERENCE TABLE — VIX & MOVE Combined Framework
B2: Matt Mattheisen-Shomer Analytics · For Internal Use Only
B4: VIX REGIME TABLE
B5: VIX Level | C5: Spread | D5: Regime | E5: TQL Action | F5: TLT Action | G5: Cash %
B6: Below 15 | C6: Negative (Contango) | D6: EQUITY TREND | E6: Full deployment, max sizing | F6: Hold / no tactical add | G6: 20-30%
